import unittest
import sys, os
import json
sys.path.append(os.getcwd())
os.environ['APP_RUN_ENV'] = 'development'

from services import diagnostics_service

class DiagnosticsTests(unittest.TestCase):
    _ = None
    def test_get_diagnostics_mutation_0(self):
        task = diagnostics_service.get_diagnostics.s(
            None, None
        ).apply()
        self.assertEqual(task.result, "[{\"time\": 1612259842, \"error_code\": 503, \"message\": \"Service down\", \"payload\": {\"payload\": \"<module 'os' from '/Library/Developer/CommandLineTools/Library/Frameworks/Python3.framework/Versions/3.7/lib/python3.7/os.py'>\"}, \"stack_trace\": \"Traceback (most recent call last):\\n  File \\\"/Users/hamedbabaeian/MergedSkyNet/Backend/core.py\\\", line 1771, in get_active_strategy_names\\n    names = _internal_task_manager.get_active_strategy_names()\\n  File \\\"/Users/hamedbabaeian/MergedSkyNet/Backend/internal_task_manager.py\\\", line 62, in get_active_strategy_names\\n    return strategies_service.get_active_strategy_names.apply_async(queue='strategies').get()\\n  File \\\"/Users/hamedbabaeian/MergedSkyNet/Backend/env/lib/python3.7/site-packages/celery/result.py\\\", line 228, in get\\n    on_message=on_message,\\n  File \\\"/Users/hamedbabaeian/MergedSkyNet/Backend/env/lib/python3.7/site-packages/celery/backends/asynchronous.py\\\", line 202, in wait_for_pending\\n    return result.maybe_throw(callback=callback, propagate=propagate)\\n  File \\\"/Users/hamedbabaeian/MergedSkyNet/Backend/env/lib/python3.7/site-packages/celery/result.py\\\", line 333, in maybe_throw\\n    self.throw(value, self._to_remote_traceback(tb))\\n  File \\\"/Users/hamedbabaeian/MergedSkyNet/Backend/env/lib/python3.7/site-packages/celery/result.py\\\", line 326, in throw\\n    self.on_ready.throw(*args, **kwargs)\\n  File \\\"/Users/hamedbabaeian/MergedSkyNet/Backend/env/lib/python3.7/site-packages/vine/promises.py\\\", line 244, in throw\\n    reraise(type(exc), exc, tb)\\n  File \\\"/Users/hamedbabaeian/MergedSkyNet/Backend/env/lib/python3.7/site-packages/vine/five.py\\\", line 195, in reraise\\n    raise value\\nFileNotFoundError: [Errno 2] No such file or directory\\n\"}, {\"time\": 1612259841, \"error_code\": 503, \"message\": \"Service down\", \"payload\": {\"payload\": \"<module 'os' from '/Library/Developer/CommandLineTools/Library/Frameworks/Python3.framework/Versions/3.7/lib/python3.7/os.py'>\"}, \"stack_trace\": \"Traceback (most recent call last):\\n  File \\\"/Users/hamedbabaeian/MergedSkyNet/Backend/core.py\\\", line 1771, in get_active_strategy_names\\n    names = _internal_task_manager.get_active_strategy_names()\\n  File \\\"/Users/hamedbabaeian/MergedSkyNet/Backend/internal_task_manager.py\\\", line 62, in get_active_strategy_names\\n    return strategies_service.get_active_strategy_names.apply_async(queue='strategies').get()\\n  File \\\"/Users/hamedbabaeian/MergedSkyNet/Backend/env/lib/python3.7/site-packages/celery/result.py\\\", line 228, in get\\n    on_message=on_message,\\n  File \\\"/Users/hamedbabaeian/MergedSkyNet/Backend/env/lib/python3.7/site-packages/celery/backends/asynchronous.py\\\", line 202, in wait_for_pending\\n    return result.maybe_throw(callback=callback, propagate=propagate)\\n  File \\\"/Users/hamedbabaeian/MergedSkyNet/Backend/env/lib/python3.7/site-packages/celery/result.py\\\", line 333, in maybe_throw\\n    self.throw(value, self._to_remote_traceback(tb))\\n  File \\\"/Users/hamedbabaeian/MergedSkyNet/Backend/env/lib/python3.7/site-packages/celery/result.py\\\", line 326, in throw\\n    self.on_ready.throw(*args, **kwargs)\\n  File \\\"/Users/hamedbabaeian/MergedSkyNet/Backend/env/lib/python3.7/site-packages/vine/promises.py\\\", line 244, in throw\\n    reraise(type(exc), exc, tb)\\n  File \\\"/Users/hamedbabaeian/MergedSkyNet/Backend/env/lib/python3.7/site-packages/vine/five.py\\\", line 195, in reraise\\n    raise value\\nFileNotFoundError: [Errno 2] No such file or directory\\n\"}, {\"time\": 1612259818, \"error_code\": 503, \"message\": \"Service down\", \"payload\": {\"payload\": \"<module 'os' from '/Library/Developer/CommandLineTools/Library/Frameworks/Python3.framework/Versions/3.7/lib/python3.7/os.py'>\"}, \"stack_trace\": \"Traceback (most recent call last):\\n  File \\\"/Users/hamedbabaeian/MergedSkyNet/Backend/core.py\\\", line 1771, in get_active_strategy_names\\n    names = _internal_task_manager.get_active_strategy_names()\\n  File \\\"/Users/hamedbabaeian/MergedSkyNet/Backend/internal_task_manager.py\\\", line 62, in get_active_strategy_names\\n    return strategies_service.get_active_strategy_names.apply_async(queue='strategies').get()\\n  File \\\"/Users/hamedbabaeian/MergedSkyNet/Backend/env/lib/python3.7/site-packages/celery/result.py\\\", line 228, in get\\n    on_message=on_message,\\n  File \\\"/Users/hamedbabaeian/MergedSkyNet/Backend/env/lib/python3.7/site-packages/celery/backends/asynchronous.py\\\", line 202, in wait_for_pending\\n    return result.maybe_throw(callback=callback, propagate=propagate)\\n  File \\\"/Users/hamedbabaeian/MergedSkyNet/Backend/env/lib/python3.7/site-packages/celery/result.py\\\", line 333, in maybe_throw\\n    self.throw(value, self._to_remote_traceback(tb))\\n  File \\\"/Users/hamedbabaeian/MergedSkyNet/Backend/env/lib/python3.7/site-packages/celery/result.py\\\", line 326, in throw\\n    self.on_ready.throw(*args, **kwargs)\\n  File \\\"/Users/hamedbabaeian/MergedSkyNet/Backend/env/lib/python3.7/site-packages/vine/promises.py\\\", line 244, in throw\\n    reraise(type(exc), exc, tb)\\n  File \\\"/Users/hamedbabaeian/MergedSkyNet/Backend/env/lib/python3.7/site-packages/vine/five.py\\\", line 195, in reraise\\n    raise value\\nFileNotFoundError: [Errno 2] No such file or directory\\n\"}, {\"time\": 1612259817, \"error_code\": 503, \"message\": \"Service down\", \"payload\": {\"payload\": \"<module 'os' from '/Library/Developer/CommandLineTools/Library/Frameworks/Python3.framework/Versions/3.7/lib/python3.7/os.py'>\"}, \"stack_trace\": \"Traceback (most recent call last):\\n  File \\\"/Users/hamedbabaeian/MergedSkyNet/Backend/core.py\\\", line 1771, in get_active_strategy_names\\n    names = _internal_task_manager.get_active_strategy_names()\\n  File \\\"/Users/hamedbabaeian/MergedSkyNet/Backend/internal_task_manager.py\\\", line 62, in get_active_strategy_names\\n    return strategies_service.get_active_strategy_names.apply_async(queue='strategies').get()\\n  File \\\"/Users/hamedbabaeian/MergedSkyNet/Backend/env/lib/python3.7/site-packages/celery/result.py\\\", line 228, in get\\n    on_message=on_message,\\n  File \\\"/Users/hamedbabaeian/MergedSkyNet/Backend/env/lib/python3.7/site-packages/celery/backends/asynchronous.py\\\", line 202, in wait_for_pending\\n    return result.maybe_throw(callback=callback, propagate=propagate)\\n  File \\\"/Users/hamedbabaeian/MergedSkyNet/Backend/env/lib/python3.7/site-packages/celery/result.py\\\", line 333, in maybe_throw\\n    self.throw(value, self._to_remote_traceback(tb))\\n  File \\\"/Users/hamedbabaeian/MergedSkyNet/Backend/env/lib/python3.7/site-packages/celery/result.py\\\", line 326, in throw\\n    self.on_ready.throw(*args, **kwargs)\\n  File \\\"/Users/hamedbabaeian/MergedSkyNet/Backend/env/lib/python3.7/site-packages/vine/promises.py\\\", line 244, in throw\\n    reraise(type(exc), exc, tb)\\n  File \\\"/Users/hamedbabaeian/MergedSkyNet/Backend/env/lib/python3.7/site-packages/vine/five.py\\\", line 195, in reraise\\n    raise value\\nFileNotFoundError: [Errno 2] No such file or directory\\n\"}, {\"time\": 1612259791, \"error_code\": 503, \"message\": \"Service down\", \"payload\": {\"payload\": \"<module 'os' from '/Library/Developer/CommandLineTools/Library/Frameworks/Python3.framework/Versions/3.7/lib/python3.7/os.py'>\"}, \"stack_trace\": \"Traceback (most recent call last):\\n  File \\\"/Users/hamedbabaeian/MergedSkyNet/Backend/core.py\\\", line 1771, in get_active_strategy_names\\n    names = _internal_task_manager.get_active_strategy_names()\\n  File \\\"/Users/hamedbabaeian/MergedSkyNet/Backend/internal_task_manager.py\\\", line 62, in get_active_strategy_names\\n    return strategies_service.get_active_strategy_names.apply_async(queue='strategies').get()\\n  File \\\"/Users/hamedbabaeian/MergedSkyNet/Backend/env/lib/python3.7/site-packages/celery/result.py\\\", line 228, in get\\n    on_message=on_message,\\n  File \\\"/Users/hamedbabaeian/MergedSkyNet/Backend/env/lib/python3.7/site-packages/celery/backends/asynchronous.py\\\", line 202, in wait_for_pending\\n    return result.maybe_throw(callback=callback, propagate=propagate)\\n  File \\\"/Users/hamedbabaeian/MergedSkyNet/Backend/env/lib/python3.7/site-packages/celery/result.py\\\", line 333, in maybe_throw\\n    self.throw(value, self._to_remote_traceback(tb))\\n  File \\\"/Users/hamedbabaeian/MergedSkyNet/Backend/env/lib/python3.7/site-packages/celery/result.py\\\", line 326, in throw\\n    self.on_ready.throw(*args, **kwargs)\\n  File \\\"/Users/hamedbabaeian/MergedSkyNet/Backend/env/lib/python3.7/site-packages/vine/promises.py\\\", line 244, in throw\\n    reraise(type(exc), exc, tb)\\n  File \\\"/Users/hamedbabaeian/MergedSkyNet/Backend/env/lib/python3.7/site-packages/vine/five.py\\\", line 195, in reraise\\n    raise value\\nFileNotFoundError: [Errno 2] No such file or directory\\n\"}, {\"time\": 1612259790, \"error_code\": 503, \"message\": \"Service down\", \"payload\": {\"payload\": \"<module 'os' from '/Library/Developer/CommandLineTools/Library/Frameworks/Python3.framework/Versions/3.7/lib/python3.7/os.py'>\"}, \"stack_trace\": \"Traceback (most recent call last):\\n  File \\\"/Users/hamedbabaeian/MergedSkyNet/Backend/core.py\\\", line 1771, in get_active_strategy_names\\n    names = _internal_task_manager.get_active_strategy_names()\\n  File \\\"/Users/hamedbabaeian/MergedSkyNet/Backend/internal_task_manager.py\\\", line 62, in get_active_strategy_names\\n    return strategies_service.get_active_strategy_names.apply_async(queue='strategies').get()\\n  File \\\"/Users/hamedbabaeian/MergedSkyNet/Backend/env/lib/python3.7/site-packages/celery/result.py\\\", line 228, in get\\n    on_message=on_message,\\n  File \\\"/Users/hamedbabaeian/MergedSkyNet/Backend/env/lib/python3.7/site-packages/celery/backends/asynchronous.py\\\", line 202, in wait_for_pending\\n    return result.maybe_throw(callback=callback, propagate=propagate)\\n  File \\\"/Users/hamedbabaeian/MergedSkyNet/Backend/env/lib/python3.7/site-packages/celery/result.py\\\", line 333, in maybe_throw\\n    self.throw(value, self._to_remote_traceback(tb))\\n  File \\\"/Users/hamedbabaeian/MergedSkyNet/Backend/env/lib/python3.7/site-packages/celery/result.py\\\", line 326, in throw\\n    self.on_ready.throw(*args, **kwargs)\\n  File \\\"/Users/hamedbabaeian/MergedSkyNet/Backend/env/lib/python3.7/site-packages/vine/promises.py\\\", line 244, in throw\\n    reraise(type(exc), exc, tb)\\n  File \\\"/Users/hamedbabaeian/MergedSkyNet/Backend/env/lib/python3.7/site-packages/vine/five.py\\\", line 195, in reraise\\n    raise value\\nFileNotFoundError: [Errno 2] No such file or directory\\n\"}, {\"time\": 1612259713, \"error_code\": 503, \"message\": \"Service down\", \"payload\": {\"payload\": \"404 Client Error: Not Found for url: https://sandbox.swiftdil.com/v1/customers/TODO/documents\"}, \"stack_trace\": \"Traceback (most recent call last):\\n  File \\\"/Users/hamedbabaeian/MergedSkyNet/Backend/core.py\\\", line 845, in get_documents\\n    documents = _task_manager.get_documents(customer_id)\\n  File \\\"/Users/hamedbabaeian/MergedSkyNet/Backend/task_manager.py\\\", line 148, in get_documents\\n    args=(customer_id,), queue='file').get()\\n  File \\\"/Users/hamedbabaeian/MergedSkyNet/Backend/env/lib/python3.7/site-packages/celery/result.py\\\", line 228, in get\\n    on_message=on_message,\\n  File \\\"/Users/hamedbabaeian/MergedSkyNet/Backend/env/lib/python3.7/site-packages/celery/backends/asynchronous.py\\\", line 202, in wait_for_pending\\n    return result.maybe_throw(callback=callback, propagate=propagate)\\n  File \\\"/Users/hamedbabaeian/MergedSkyNet/Backend/env/lib/python3.7/site-packages/celery/result.py\\\", line 333, in maybe_throw\\n    self.throw(value, self._to_remote_traceback(tb))\\n  File \\\"/Users/hamedbabaeian/MergedSkyNet/Backend/env/lib/python3.7/site-packages/celery/result.py\\\", line 326, in throw\\n    self.on_ready.throw(*args, **kwargs)\\n  File \\\"/Users/hamedbabaeian/MergedSkyNet/Backend/env/lib/python3.7/site-packages/vine/promises.py\\\", line 244, in throw\\n    reraise(type(exc), exc, tb)\\n  File \\\"/Users/hamedbabaeian/MergedSkyNet/Backend/env/lib/python3.7/site-packages/vine/five.py\\\", line 195, in reraise\\n    raise value\\nrequests.exceptions.HTTPError: 404 Client Error: Not Found for url: https://sandbox.swiftdil.com/v1/customers/TODO/documents\\n\"}, {\"time\": 1612259713, \"error_code\": 503, \"message\": \"Service down\", \"payload\": {\"payload\": \"404 Client Error: Not Found for url: https://sandbox.swiftdil.com/v1/customers/TODO/screenings?size=20&page=0&sort=createdDate%2CDESC\"}, \"stack_trace\": \"Traceback (most recent call last):\\n  File \\\"/Users/hamedbabaeian/MergedSkyNet/Backend/core.py\\\", line 689, in get_screenings\\n    end=request.args.get('end', None))\\n  File \\\"/Users/hamedbabaeian/MergedSkyNet/Backend/task_manager.py\\\", line 99, in get_screenings\\n    created_after=begin, created_before=end).get()\\n  File \\\"/Users/hamedbabaeian/MergedSkyNet/Backend/env/lib/python3.7/site-packages/celery/result.py\\\", line 228, in get\\n    on_message=on_message,\\n  File \\\"/Users/hamedbabaeian/MergedSkyNet/Backend/env/lib/python3.7/site-packages/celery/backends/asynchronous.py\\\", line 202, in wait_for_pending\\n    return result.maybe_throw(callback=callback, propagate=propagate)\\n  File \\\"/Users/hamedbabaeian/MergedSkyNet/Backend/env/lib/python3.7/site-packages/celery/result.py\\\", line 333, in maybe_throw\\n    self.throw(value, self._to_remote_traceback(tb))\\n  File \\\"/Users/hamedbabaeian/MergedSkyNet/Backend/env/lib/python3.7/site-packages/celery/result.py\\\", line 326, in throw\\n    self.on_ready.throw(*args, **kwargs)\\n  File \\\"/Users/hamedbabaeian/MergedSkyNet/Backend/env/lib/python3.7/site-packages/vine/promises.py\\\", line 244, in throw\\n    reraise(type(exc), exc, tb)\\n  File \\\"/Users/hamedbabaeian/MergedSkyNet/Backend/env/lib/python3.7/site-packages/vine/five.py\\\", line 195, in reraise\\n    raise value\\nrequests.exceptions.HTTPError: 404 Client Error: Not Found for url: https://sandbox.swiftdil.com/v1/customers/TODO/screenings?size=20&page=0&sort=createdDate%2CDESC\\n\"}, {\"time\": 1612259712, \"error_code\": 503, \"message\": \"Service down\", \"payload\": {\"payload\": \"404 Client Error: Not Found for url: https://sandbox.swiftdil.com/v1/customers/TODO/risk_profile\"}, \"stack_trace\": \"Traceback (most recent call last):\\n  File \\\"/Users/hamedbabaeian/MergedSkyNet/Backend/core.py\\\", line 561, in get_customer_risk\\n    risk = _task_manager.get_customer_risk(customer_id)\\n  File \\\"/Users/hamedbabaeian/MergedSkyNet/Backend/task_manager.py\\\", line 49, in get_customer_risk\\n    args=(customer_id,), queue='customers').get()\\n  File \\\"/Users/hamedbabaeian/MergedSkyNet/Backend/env/lib/python3.7/site-packages/celery/result.py\\\", line 228, in get\\n    on_message=on_message,\\n  File \\\"/Users/hamedbabaeian/MergedSkyNet/Backend/env/lib/python3.7/site-packages/celery/backends/asynchronous.py\\\", line 202, in wait_for_pending\\n    return result.maybe_throw(callback=callback, propagate=propagate)\\n  File \\\"/Users/hamedbabaeian/MergedSkyNet/Backend/env/lib/python3.7/site-packages/celery/result.py\\\", line 333, in maybe_throw\\n    self.throw(value, self._to_remote_traceback(tb))\\n  File \\\"/Users/hamedbabaeian/MergedSkyNet/Backend/env/lib/python3.7/site-packages/celery/result.py\\\", line 326, in throw\\n    self.on_ready.throw(*args, **kwargs)\\n  File \\\"/Users/hamedbabaeian/MergedSkyNet/Backend/env/lib/python3.7/site-packages/vine/promises.py\\\", line 244, in throw\\n    reraise(type(exc), exc, tb)\\n  File \\\"/Users/hamedbabaeian/MergedSkyNet/Backend/env/lib/python3.7/site-packages/vine/five.py\\\", line 195, in reraise\\n    raise value\\nrequests.exceptions.HTTPError: 404 Client Error: Not Found for url: https://sandbox.swiftdil.com/v1/customers/TODO/risk_profile\\n\"}, {\"time\": 1612259711, \"error_code\": 503, \"message\": \"Service down\", \"payload\": {\"payload\": \"404 Client Error: Not Found for url: https://sandbox.swiftdil.com/v1/customers/TODO\"}, \"stack_trace\": \"Traceback (most recent call last):\\n  File \\\"/Users/hamedbabaeian/MergedSkyNet/Backend/core.py\\\", line 544, in get_customer\\n    customer = _task_manager.get_customer(customer_id)\\n  File \\\"/Users/hamedbabaeian/MergedSkyNet/Backend/task_manager.py\\\", line 45, in get_customer\\n    args=(customer_id,), queue='customers').get()\\n  File \\\"/Users/hamedbabaeian/MergedSkyNet/Backend/env/lib/python3.7/site-packages/celery/result.py\\\", line 228, in get\\n    on_message=on_message,\\n  File \\\"/Users/hamedbabaeian/MergedSkyNet/Backend/env/lib/python3.7/site-packages/celery/backends/asynchronous.py\\\", line 202, in wait_for_pending\\n    return result.maybe_throw(callback=callback, propagate=propagate)\\n  File \\\"/Users/hamedbabaeian/MergedSkyNet/Backend/env/lib/python3.7/site-packages/celery/result.py\\\", line 333, in maybe_throw\\n    self.throw(value, self._to_remote_traceback(tb))\\n  File \\\"/Users/hamedbabaeian/MergedSkyNet/Backend/env/lib/python3.7/site-packages/celery/result.py\\\", line 326, in throw\\n    self.on_ready.throw(*args, **kwargs)\\n  File \\\"/Users/hamedbabaeian/MergedSkyNet/Backend/env/lib/python3.7/site-packages/vine/promises.py\\\", line 244, in throw\\n    reraise(type(exc), exc, tb)\\n  File \\\"/Users/hamedbabaeian/MergedSkyNet/Backend/env/lib/python3.7/site-packages/vine/five.py\\\", line 195, in reraise\\n    raise value\\nrequests.exceptions.HTTPError: 404 Client Error: Not Found for url: https://sandbox.swiftdil.com/v1/customers/TODO\\n\"}, {\"time\": 1612259711, \"error_code\": 503, \"message\": \"Service down\", \"payload\": {\"payload\": \"404 Client Error: Not Found for url: https://sandbox.swiftdil.com/v1/customers/TODO/odd?size=7\"}, \"stack_trace\": \"Traceback (most recent call last):\\n  File \\\"/Users/hamedbabaeian/MergedSkyNet/Backend/core.py\\\", line 758, in get_odds\\n    request.args.get('end', None))\\n  File \\\"/Users/hamedbabaeian/MergedSkyNet/Backend/task_manager.py\\\", line 123, in get_odds\\n    created_before=end).get()\\n  File \\\"/Users/hamedbabaeian/MergedSkyNet/Backend/env/lib/python3.7/site-packages/celery/result.py\\\", line 228, in get\\n    on_message=on_message,\\n  File \\\"/Users/hamedbabaeian/MergedSkyNet/Backend/env/lib/python3.7/site-packages/celery/backends/asynchronous.py\\\", line 202, in wait_for_pending\\n    return result.maybe_throw(callback=callback, propagate=propagate)\\n  File \\\"/Users/hamedbabaeian/MergedSkyNet/Backend/env/lib/python3.7/site-packages/celery/result.py\\\", line 333, in maybe_throw\\n    self.throw(value, self._to_remote_traceback(tb))\\n  File \\\"/Users/hamedbabaeian/MergedSkyNet/Backend/env/lib/python3.7/site-packages/celery/result.py\\\", line 326, in throw\\n    self.on_ready.throw(*args, **kwargs)\\n  File \\\"/Users/hamedbabaeian/MergedSkyNet/Backend/env/lib/python3.7/site-packages/vine/promises.py\\\", line 244, in throw\\n    reraise(type(exc), exc, tb)\\n  File \\\"/Users/hamedbabaeian/MergedSkyNet/Backend/env/lib/python3.7/site-packages/vine/five.py\\\", line 195, in reraise\\n    raise value\\nrequests.exceptions.HTTPError: 404 Client Error: Not Found for url: https://sandbox.swiftdil.com/v1/customers/TODO/odd?size=7\\n\"}, {\"time\": 1612259711, \"error_code\": 503, \"message\": \"Service down\", \"payload\": {\"payload\": \"404 Client Error: Not Found for url: https://sandbox.swiftdil.com/v1/customers/TODO/screenings?size=20&page=0&sort=createdDate%2CDESC\"}, \"stack_trace\": \"Traceback (most recent call last):\\n  File \\\"/Users/hamedbabaeian/MergedSkyNet/Backend/core.py\\\", line 689, in get_screenings\\n    end=request.args.get('end', None))\\n  File \\\"/Users/hamedbabaeian/MergedSkyNet/Backend/task_manager.py\\\", line 99, in get_screenings\\n    created_after=begin, created_before=end).get()\\n  File \\\"/Users/hamedbabaeian/MergedSkyNet/Backend/env/lib/python3.7/site-packages/celery/result.py\\\", line 228, in get\\n    on_message=on_message,\\n  File \\\"/Users/hamedbabaeian/MergedSkyNet/Backend/env/lib/python3.7/site-packages/celery/backends/asynchronous.py\\\", line 202, in wait_for_pending\\n    return result.maybe_throw(callback=callback, propagate=propagate)\\n  File \\\"/Users/hamedbabaeian/MergedSkyNet/Backend/env/lib/python3.7/site-packages/celery/result.py\\\", line 333, in maybe_throw\\n    self.throw(value, self._to_remote_traceback(tb))\\n  File \\\"/Users/hamedbabaeian/MergedSkyNet/Backend/env/lib/python3.7/site-packages/celery/result.py\\\", line 326, in throw\\n    self.on_ready.throw(*args, **kwargs)\\n  File \\\"/Users/hamedbabaeian/MergedSkyNet/Backend/env/lib/python3.7/site-packages/vine/promises.py\\\", line 244, in throw\\n    reraise(type(exc), exc, tb)\\n  File \\\"/Users/hamedbabaeian/MergedSkyNet/Backend/env/lib/python3.7/site-packages/vine/five.py\\\", line 195, in reraise\\n    raise value\\nrequests.exceptions.HTTPError: 404 Client Error: Not Found for url: https://sandbox.swiftdil.com/v1/customers/TODO/screenings?size=20&page=0&sort=createdDate%2CDESC\\n\"}, {\"time\": 1612259711, \"error_code\": 503, \"message\": \"Service down\", \"payload\": {\"payload\": \"404 Client Error: Not Found for url: https://sandbox.swiftdil.com/v1/customers/TODO/documents\"}, \"stack_trace\": \"Traceback (most recent call last):\\n  File \\\"/Users/hamedbabaeian/MergedSkyNet/Backend/core.py\\\", line 845, in get_documents\\n    documents = _task_manager.get_documents(customer_id)\\n  File \\\"/Users/hamedbabaeian/MergedSkyNet/Backend/task_manager.py\\\", line 148, in get_documents\\n    args=(customer_id,), queue='file').get()\\n  File \\\"/Users/hamedbabaeian/MergedSkyNet/Backend/env/lib/python3.7/site-packages/celery/result.py\\\", line 228, in get\\n    on_message=on_message,\\n  File \\\"/Users/hamedbabaeian/MergedSkyNet/Backend/env/lib/python3.7/site-packages/celery/backends/asynchronous.py\\\", line 202, in wait_for_pending\\n    return result.maybe_throw(callback=callback, propagate=propagate)\\n  File \\\"/Users/hamedbabaeian/MergedSkyNet/Backend/env/lib/python3.7/site-packages/celery/result.py\\\", line 333, in maybe_throw\\n    self.throw(value, self._to_remote_traceback(tb))\\n  File \\\"/Users/hamedbabaeian/MergedSkyNet/Backend/env/lib/python3.7/site-packages/celery/result.py\\\", line 326, in throw\\n    self.on_ready.throw(*args, **kwargs)\\n  File \\\"/Users/hamedbabaeian/MergedSkyNet/Backend/env/lib/python3.7/site-packages/vine/promises.py\\\", line 244, in throw\\n    reraise(type(exc), exc, tb)\\n  File \\\"/Users/hamedbabaeian/MergedSkyNet/Backend/env/lib/python3.7/site-packages/vine/five.py\\\", line 195, in reraise\\n    raise value\\nrequests.exceptions.HTTPError: 404 Client Error: Not Found for url: https://sandbox.swiftdil.com/v1/customers/TODO/documents\\n\"}, {\"time\": 1612259710, \"error_code\": 503, \"message\": \"Service down\", \"payload\": {\"payload\": \"404 Client Error: Not Found for url: https://sandbox.swiftdil.com/v1/customers/TODO/risk_profile\"}, \"stack_trace\": \"Traceback (most recent call last):\\n  File \\\"/Users/hamedbabaeian/MergedSkyNet/Backend/core.py\\\", line 561, in get_customer_risk\\n    risk = _task_manager.get_customer_risk(customer_id)\\n  File \\\"/Users/hamedbabaeian/MergedSkyNet/Backend/task_manager.py\\\", line 49, in get_customer_risk\\n    args=(customer_id,), queue='customers').get()\\n  File \\\"/Users/hamedbabaeian/MergedSkyNet/Backend/env/lib/python3.7/site-packages/celery/result.py\\\", line 228, in get\\n    on_message=on_message,\\n  File \\\"/Users/hamedbabaeian/MergedSkyNet/Backend/env/lib/python3.7/site-packages/celery/backends/asynchronous.py\\\", line 202, in wait_for_pending\\n    return result.maybe_throw(callback=callback, propagate=propagate)\\n  File \\\"/Users/hamedbabaeian/MergedSkyNet/Backend/env/lib/python3.7/site-packages/celery/result.py\\\", line 333, in maybe_throw\\n    self.throw(value, self._to_remote_traceback(tb))\\n  File \\\"/Users/hamedbabaeian/MergedSkyNet/Backend/env/lib/python3.7/site-packages/celery/result.py\\\", line 326, in throw\\n    self.on_ready.throw(*args, **kwargs)\\n  File \\\"/Users/hamedbabaeian/MergedSkyNet/Backend/env/lib/python3.7/site-packages/vine/promises.py\\\", line 244, in throw\\n    reraise(type(exc), exc, tb)\\n  File \\\"/Users/hamedbabaeian/MergedSkyNet/Backend/env/lib/python3.7/site-packages/vine/five.py\\\", line 195, in reraise\\n    raise value\\nrequests.exceptions.HTTPError: 404 Client Error: Not Found for url: https://sandbox.swiftdil.com/v1/customers/TODO/risk_profile\\n\"}, {\"time\": 1612259710, \"error_code\": 503, \"message\": \"Service down\", \"payload\": {\"payload\": \"404 Client Error: Not Found for url: https://sandbox.swiftdil.com/v1/customers/TODO\"}, \"stack_trace\": \"Traceback (most recent call last):\\n  File \\\"/Users/hamedbabaeian/MergedSkyNet/Backend/core.py\\\", line 544, in get_customer\\n    customer = _task_manager.get_customer(customer_id)\\n  File \\\"/Users/hamedbabaeian/MergedSkyNet/Backend/task_manager.py\\\", line 45, in get_customer\\n    args=(customer_id,), queue='customers').get()\\n  File \\\"/Users/hamedbabaeian/MergedSkyNet/Backend/env/lib/python3.7/site-packages/celery/result.py\\\", line 228, in get\\n    on_message=on_message,\\n  File \\\"/Users/hamedbabaeian/MergedSkyNet/Backend/env/lib/python3.7/site-packages/celery/backends/asynchronous.py\\\", line 202, in wait_for_pending\\n    return result.maybe_throw(callback=callback, propagate=propagate)\\n  File \\\"/Users/hamedbabaeian/MergedSkyNet/Backend/env/lib/python3.7/site-packages/celery/result.py\\\", line 333, in maybe_throw\\n    self.throw(value, self._to_remote_traceback(tb))\\n  File \\\"/Users/hamedbabaeian/MergedSkyNet/Backend/env/lib/python3.7/site-packages/celery/result.py\\\", line 326, in throw\\n    self.on_ready.throw(*args, **kwargs)\\n  File \\\"/Users/hamedbabaeian/MergedSkyNet/Backend/env/lib/python3.7/site-packages/vine/promises.py\\\", line 244, in throw\\n    reraise(type(exc), exc, tb)\\n  File \\\"/Users/hamedbabaeian/MergedSkyNet/Backend/env/lib/python3.7/site-packages/vine/five.py\\\", line 195, in reraise\\n    raise value\\nrequests.exceptions.HTTPError: 404 Client Error: Not Found for url: https://sandbox.swiftdil.com/v1/customers/TODO\\n\"}, {\"time\": 1612259710, \"error_code\": 503, \"message\": \"Service down\", \"payload\": {\"payload\": \"404 Client Error: Not Found for url: https://sandbox.swiftdil.com/v1/customers/TODO/odd?size=7\"}, \"stack_trace\": \"Traceback (most recent call last):\\n  File \\\"/Users/hamedbabaeian/MergedSkyNet/Backend/core.py\\\", line 758, in get_odds\\n    request.args.get('end', None))\\n  File \\\"/Users/hamedbabaeian/MergedSkyNet/Backend/task_manager.py\\\", line 123, in get_odds\\n    created_before=end).get()\\n  File \\\"/Users/hamedbabaeian/MergedSkyNet/Backend/env/lib/python3.7/site-packages/celery/result.py\\\", line 228, in get\\n    on_message=on_message,\\n  File \\\"/Users/hamedbabaeian/MergedSkyNet/Backend/env/lib/python3.7/site-packages/celery/backends/asynchronous.py\\\", line 202, in wait_for_pending\\n    return result.maybe_throw(callback=callback, propagate=propagate)\\n  File \\\"/Users/hamedbabaeian/MergedSkyNet/Backend/env/lib/python3.7/site-packages/celery/result.py\\\", line 333, in maybe_throw\\n    self.throw(value, self._to_remote_traceback(tb))\\n  File \\\"/Users/hamedbabaeian/MergedSkyNet/Backend/env/lib/python3.7/site-packages/celery/result.py\\\", line 326, in throw\\n    self.on_ready.throw(*args, **kwargs)\\n  File \\\"/Users/hamedbabaeian/MergedSkyNet/Backend/env/lib/python3.7/site-packages/vine/promises.py\\\", line 244, in throw\\n    reraise(type(exc), exc, tb)\\n  File \\\"/Users/hamedbabaeian/MergedSkyNet/Backend/env/lib/python3.7/site-packages/vine/five.py\\\", line 195, in reraise\\n    raise value\\nrequests.exceptions.HTTPError: 404 Client Error: Not Found for url: https://sandbox.swiftdil.com/v1/customers/TODO/odd?size=7\\n\"}, {\"time\": 1612259710, \"error_code\": 503, \"message\": \"Service down\", \"payload\": {\"payload\": \"[Errno 2] No such file or directory\"}, \"stack_trace\": \"Traceback (most recent call last):\\n  File \\\"/Users/hamedbabaeian/MergedSkyNet/Backend/core.py\\\", line 2023, in get_withdrawable_amount\\n    amount = _internal_task_manager.get_withdrawable_amount(user_id)\\n  File \\\"/Users/hamedbabaeian/MergedSkyNet/Backend/internal_task_manager.py\\\", line 274, in get_withdrawable_amount\\n    return {**amount_task_dump.get(), **amount_task.get()}\\n  File \\\"/Users/hamedbabaeian/MergedSkyNet/Backend/env/lib/python3.7/site-packages/celery/result.py\\\", line 211, in get\\n    self._maybe_reraise_parent_error()\\n  File \\\"/Users/hamedbabaeian/MergedSkyNet/Backend/env/lib/python3.7/site-packages/celery/result.py\\\", line 234, in _maybe_reraise_parent_error\\n    node.maybe_throw()\\n  File \\\"/Users/hamedbabaeian/MergedSkyNet/Backend/env/lib/python3.7/site-packages/celery/result.py\\\", line 333, in maybe_throw\\n    self.throw(value, self._to_remote_traceback(tb))\\n  File \\\"/Users/hamedbabaeian/MergedSkyNet/Backend/env/lib/python3.7/site-packages/celery/result.py\\\", line 326, in throw\\n    self.on_ready.throw(*args, **kwargs)\\n  File \\\"/Users/hamedbabaeian/MergedSkyNet/Backend/env/lib/python3.7/site-packages/vine/promises.py\\\", line 244, in throw\\n    reraise(type(exc), exc, tb)\\n  File \\\"/Users/hamedbabaeian/MergedSkyNet/Backend/env/lib/python3.7/site-packages/vine/five.py\\\", line 195, in reraise\\n    raise value\\nFileNotFoundError: [Errno 2] No such file or directory\\n\"}, {\"time\": 1612259709, \"error_code\": 503, \"message\": \"Service down\", \"payload\": {\"payload\": \"[Errno 2] No such file or directory\"}, \"stack_trace\": \"Traceback (most recent call last):\\n  File \\\"/Users/hamedbabaeian/MergedSkyNet/Backend/core.py\\\", line 352, in get_user_timeline\\n    result = _internal_task_manager.get_user_timeline(user_id)\\n  File \\\"/Users/hamedbabaeian/MergedSkyNet/Backend/internal_task_manager.py\\\", line 243, in get_user_timeline\\n    for sb in subscription_tasks.get(): result.extend(json.loads(sb))\\n  File \\\"/Users/hamedbabaeian/MergedSkyNet/Backend/env/lib/python3.7/site-packages/celery/result.py\\\", line 703, in get\\n    on_interval=on_interval,\\n  File \\\"/Users/hamedbabaeian/MergedSkyNet/Backend/env/lib/python3.7/site-packages/celery/result.py\\\", line 830, in join_native\\n    raise value\\nFileNotFoundError: [Errno 2] No such file or directory\\n\"}, {\"time\": 1612259707, \"error_code\": 503, \"message\": \"Service down\", \"payload\": {\"payload\": \"[Errno 2] No such file or directory\"}, \"stack_trace\": \"Traceback (most recent call last):\\n  File \\\"/Users/hamedbabaeian/MergedSkyNet/Backend/core.py\\\", line 1059, in get_user_subscribed_strategies\\n    end=end)\\n  File \\\"/Users/hamedbabaeian/MergedSkyNet/Backend/internal_task_manager.py\\\", line 98, in get_user_subscribed_strategies\\n    args=(user_id, int(size), int(page), sort, order, begin, end), queue='strategies').get()\\n  File \\\"/Users/hamedbabaeian/MergedSkyNet/Backend/env/lib/python3.7/site-packages/celery/result.py\\\", line 228, in get\\n    on_message=on_message,\\n  File \\\"/Users/hamedbabaeian/MergedSkyNet/Backend/env/lib/python3.7/site-packages/celery/backends/asynchronous.py\\\", line 202, in wait_for_pending\\n    return result.maybe_throw(callback=callback, propagate=propagate)\\n  File \\\"/Users/hamedbabaeian/MergedSkyNet/Backend/env/lib/python3.7/site-packages/celery/result.py\\\", line 333, in maybe_throw\\n    self.throw(value, self._to_remote_traceback(tb))\\n  File \\\"/Users/hamedbabaeian/MergedSkyNet/Backend/env/lib/python3.7/site-packages/celery/result.py\\\", line 326, in throw\\n    self.on_ready.throw(*args, **kwargs)\\n  File \\\"/Users/hamedbabaeian/MergedSkyNet/Backend/env/lib/python3.7/site-packages/vine/promises.py\\\", line 244, in throw\\n    reraise(type(exc), exc, tb)\\n  File \\\"/Users/hamedbabaeian/MergedSkyNet/Backend/env/lib/python3.7/site-packages/vine/five.py\\\", line 195, in reraise\\n    raise value\\nFileNotFoundError: [Errno 2] No such file or directory\\n\"}, {\"time\": 1612259707, \"error_code\": 503, \"message\": \"Service down\", \"payload\": {\"payload\": \"[Errno 2] No such file or directory\"}, \"stack_trace\": \"Traceback (most recent call last):\\n  File \\\"/Users/hamedbabaeian/MergedSkyNet/Backend/core.py\\\", line 1088, in get_user_unsubscribed_strategies\\n    end=end)\\n  File \\\"/Users/hamedbabaeian/MergedSkyNet/Backend/internal_task_manager.py\\\", line 103, in get_user_unsubscribed_strategies\\n    args=(user_id, int(size), int(page), sort, order, begin, end), queue='strategies').get()\\n  File \\\"/Users/hamedbabaeian/MergedSkyNet/Backend/env/lib/python3.7/site-packages/celery/result.py\\\", line 228, in get\\n    on_message=on_message,\\n  File \\\"/Users/hamedbabaeian/MergedSkyNet/Backend/env/lib/python3.7/site-packages/celery/backends/asynchronous.py\\\", line 202, in wait_for_pending\\n    return result.maybe_throw(callback=callback, propagate=propagate)\\n  File \\\"/Users/hamedbabaeian/MergedSkyNet/Backend/env/lib/python3.7/site-packages/celery/result.py\\\", line 333, in maybe_throw\\n    self.throw(value, self._to_remote_traceback(tb))\\n  File \\\"/Users/hamedbabaeian/MergedSkyNet/Backend/env/lib/python3.7/site-packages/celery/result.py\\\", line 326, in throw\\n    self.on_ready.throw(*args, **kwargs)\\n  File \\\"/Users/hamedbabaeian/MergedSkyNet/Backend/env/lib/python3.7/site-packages/vine/promises.py\\\", line 244, in throw\\n    reraise(type(exc), exc, tb)\\n  File \\\"/Users/hamedbabaeian/MergedSkyNet/Backend/env/lib/python3.7/site-packages/vine/five.py\\\", line 195, in reraise\\n    raise value\\nFileNotFoundError: [Errno 2] No such file or directory\\n\"}, {\"time\": 1612259707, \"error_code\": 503, \"message\": \"Service down\", \"payload\": {\"payload\": \"[Errno 2] No such file or directory\"}, \"stack_trace\": \"Traceback (most recent call last):\\n  File \\\"/Users/hamedbabaeian/MergedSkyNet/Backend/core.py\\\", line 2023, in get_withdrawable_amount\\n    amount = _internal_task_manager.get_withdrawable_amount(user_id)\\n  File \\\"/Users/hamedbabaeian/MergedSkyNet/Backend/internal_task_manager.py\\\", line 274, in get_withdrawable_amount\\n    return {**amount_task_dump.get(), **amount_task.get()}\\n  File \\\"/Users/hamedbabaeian/MergedSkyNet/Backend/env/lib/python3.7/site-packages/celery/result.py\\\", line 211, in get\\n    self._maybe_reraise_parent_error()\\n  File \\\"/Users/hamedbabaeian/MergedSkyNet/Backend/env/lib/python3.7/site-packages/celery/result.py\\\", line 234, in _maybe_reraise_parent_error\\n    node.maybe_throw()\\n  File \\\"/Users/hamedbabaeian/MergedSkyNet/Backend/env/lib/python3.7/site-packages/celery/result.py\\\", line 333, in maybe_throw\\n    self.throw(value, self._to_remote_traceback(tb))\\n  File \\\"/Users/hamedbabaeian/MergedSkyNet/Backend/env/lib/python3.7/site-packages/celery/result.py\\\", line 326, in throw\\n    self.on_ready.throw(*args, **kwargs)\\n  File \\\"/Users/hamedbabaeian/MergedSkyNet/Backend/env/lib/python3.7/site-packages/vine/promises.py\\\", line 244, in throw\\n    reraise(type(exc), exc, tb)\\n  File \\\"/Users/hamedbabaeian/MergedSkyNet/Backend/env/lib/python3.7/site-packages/vine/five.py\\\", line 195, in reraise\\n    raise value\\nFileNotFoundError: [Errno 2] No such file or directory\\n\"}, {\"time\": 1612259707, \"error_code\": 503, \"message\": \"Service down\", \"payload\": {\"payload\": \"[Errno 2] No such file or directory\"}, \"stack_trace\": \"Traceback (most recent call last):\\n  File \\\"/Users/hamedbabaeian/MergedSkyNet/Backend/core.py\\\", line 352, in get_user_timeline\\n    result = _internal_task_manager.get_user_timeline(user_id)\\n  File \\\"/Users/hamedbabaeian/MergedSkyNet/Backend/internal_task_manager.py\\\", line 243, in get_user_timeline\\n    for sb in subscription_tasks.get(): result.extend(json.loads(sb))\\n  File \\\"/Users/hamedbabaeian/MergedSkyNet/Backend/env/lib/python3.7/site-packages/celery/result.py\\\", line 703, in get\\n    on_interval=on_interval,\\n  File \\\"/Users/hamedbabaeian/MergedSkyNet/Backend/env/lib/python3.7/site-packages/celery/result.py\\\", line 830, in join_native\\n    raise value\\nFileNotFoundError: [Errno 2] No such file or directory\\n\"}, {\"time\": 1612259706, \"error_code\": 503, \"message\": \"Service down\", \"payload\": {\"payload\": \"[Errno 2] No such file or directory\"}, \"stack_trace\": \"Traceback (most recent call last):\\n  File \\\"/Users/hamedbabaeian/MergedSkyNet/Backend/core.py\\\", line 1059, in get_user_subscribed_strategies\\n    end=end)\\n  File \\\"/Users/hamedbabaeian/MergedSkyNet/Backend/internal_task_manager.py\\\", line 98, in get_user_subscribed_strategies\\n    args=(user_id, int(size), int(page), sort, order, begin, end), queue='strategies').get()\\n  File \\\"/Users/hamedbabaeian/MergedSkyNet/Backend/env/lib/python3.7/site-packages/celery/result.py\\\", line 228, in get\\n    on_message=on_message,\\n  File \\\"/Users/hamedbabaeian/MergedSkyNet/Backend/env/lib/python3.7/site-packages/celery/backends/asynchronous.py\\\", line 202, in wait_for_pending\\n    return result.maybe_throw(callback=callback, propagate=propagate)\\n  File \\\"/Users/hamedbabaeian/MergedSkyNet/Backend/env/lib/python3.7/site-packages/celery/result.py\\\", line 333, in maybe_throw\\n    self.throw(value, self._to_remote_traceback(tb))\\n  File \\\"/Users/hamedbabaeian/MergedSkyNet/Backend/env/lib/python3.7/site-packages/celery/result.py\\\", line 326, in throw\\n    self.on_ready.throw(*args, **kwargs)\\n  File \\\"/Users/hamedbabaeian/MergedSkyNet/Backend/env/lib/python3.7/site-packages/vine/promises.py\\\", line 244, in throw\\n    reraise(type(exc), exc, tb)\\n  File \\\"/Users/hamedbabaeian/MergedSkyNet/Backend/env/lib/python3.7/site-packages/vine/five.py\\\", line 195, in reraise\\n    raise value\\nFileNotFoundError: [Errno 2] No such file or directory\\n\"}, {\"time\": 1612259706, \"error_code\": 503, \"message\": \"Service down\", \"payload\": {\"payload\": \"[Errno 2] No such file or directory\"}, \"stack_trace\": \"Traceback (most recent call last):\\n  File \\\"/Users/hamedbabaeian/MergedSkyNet/Backend/core.py\\\", line 1088, in get_user_unsubscribed_strategies\\n    end=end)\\n  File \\\"/Users/hamedbabaeian/MergedSkyNet/Backend/internal_task_manager.py\\\", line 103, in get_user_unsubscribed_strategies\\n    args=(user_id, int(size), int(page), sort, order, begin, end), queue='strategies').get()\\n  File \\\"/Users/hamedbabaeian/MergedSkyNet/Backend/env/lib/python3.7/site-packages/celery/result.py\\\", line 228, in get\\n    on_message=on_message,\\n  File \\\"/Users/hamedbabaeian/MergedSkyNet/Backend/env/lib/python3.7/site-packages/celery/backends/asynchronous.py\\\", line 202, in wait_for_pending\\n    return result.maybe_throw(callback=callback, propagate=propagate)\\n  File \\\"/Users/hamedbabaeian/MergedSkyNet/Backend/env/lib/python3.7/site-packages/celery/result.py\\\", line 333, in maybe_throw\\n    self.throw(value, self._to_remote_traceback(tb))\\n  File \\\"/Users/hamedbabaeian/MergedSkyNet/Backend/env/lib/python3.7/site-packages/celery/result.py\\\", line 326, in throw\\n    self.on_ready.throw(*args, **kwargs)\\n  File \\\"/Users/hamedbabaeian/MergedSkyNet/Backend/env/lib/python3.7/site-packages/vine/promises.py\\\", line 244, in throw\\n    reraise(type(exc), exc, tb)\\n  File \\\"/Users/hamedbabaeian/MergedSkyNet/Backend/env/lib/python3.7/site-packages/vine/five.py\\\", line 195, in reraise\\n    raise value\\nFileNotFoundError: [Errno 2] No such file or directory\\n\"}, {\"time\": 1612259697, \"error_code\": 503, \"message\": \"Service down\", \"payload\": {\"payload\": \"[Errno 2] No such file or directory\"}, \"stack_trace\": \"Traceback (most recent call last):\\n  File \\\"/Users/hamedbabaeian/MergedSkyNet/Backend/core.py\\\", line 1059, in get_user_subscribed_strategies\\n    end=end)\\n  File \\\"/Users/hamedbabaeian/MergedSkyNet/Backend/internal_task_manager.py\\\", line 98, in get_user_subscribed_strategies\\n    args=(user_id, int(size), int(page), sort, order, begin, end), queue='strategies').get()\\n  File \\\"/Users/hamedbabaeian/MergedSkyNet/Backend/env/lib/python3.7/site-packages/celery/result.py\\\", line 228, in get\\n    on_message=on_message,\\n  File \\\"/Users/hamedbabaeian/MergedSkyNet/Backend/env/lib/python3.7/site-packages/celery/backends/asynchronous.py\\\", line 202, in wait_for_pending\\n    return result.maybe_throw(callback=callback, propagate=propagate)\\n  File \\\"/Users/hamedbabaeian/MergedSkyNet/Backend/env/lib/python3.7/site-packages/celery/result.py\\\", line 333, in maybe_throw\\n    self.throw(value, self._to_remote_traceback(tb))\\n  File \\\"/Users/hamedbabaeian/MergedSkyNet/Backend/env/lib/python3.7/site-packages/celery/result.py\\\", line 326, in throw\\n    self.on_ready.throw(*args, **kwargs)\\n  File \\\"/Users/hamedbabaeian/MergedSkyNet/Backend/env/lib/python3.7/site-packages/vine/promises.py\\\", line 244, in throw\\n    reraise(type(exc), exc, tb)\\n  File \\\"/Users/hamedbabaeian/MergedSkyNet/Backend/env/lib/python3.7/site-packages/vine/five.py\\\", line 195, in reraise\\n    raise value\\nFileNotFoundError: [Errno 2] No such file or directory\\n\"}, {\"time\": 1612259696, \"error_code\": 503, \"message\": \"Service down\", \"payload\": {\"payload\": \"[Errno 2] No such file or directory\"}, \"stack_trace\": \"Traceback (most recent call last):\\n  File \\\"/Users/hamedbabaeian/MergedSkyNet/Backend/core.py\\\", line 1059, in get_user_subscribed_strategies\\n    end=end)\\n  File \\\"/Users/hamedbabaeian/MergedSkyNet/Backend/internal_task_manager.py\\\", line 98, in get_user_subscribed_strategies\\n    args=(user_id, int(size), int(page), sort, order, begin, end), queue='strategies').get()\\n  File \\\"/Users/hamedbabaeian/MergedSkyNet/Backend/env/lib/python3.7/site-packages/celery/result.py\\\", line 228, in get\\n    on_message=on_message,\\n  File \\\"/Users/hamedbabaeian/MergedSkyNet/Backend/env/lib/python3.7/site-packages/celery/backends/asynchronous.py\\\", line 202, in wait_for_pending\\n    return result.maybe_throw(callback=callback, propagate=propagate)\\n  File \\\"/Users/hamedbabaeian/MergedSkyNet/Backend/env/lib/python3.7/site-packages/celery/result.py\\\", line 333, in maybe_throw\\n    self.throw(value, self._to_remote_traceback(tb))\\n  File \\\"/Users/hamedbabaeian/MergedSkyNet/Backend/env/lib/python3.7/site-packages/celery/result.py\\\", line 326, in throw\\n    self.on_ready.throw(*args, **kwargs)\\n  File \\\"/Users/hamedbabaeian/MergedSkyNet/Backend/env/lib/python3.7/site-packages/vine/promises.py\\\", line 244, in throw\\n    reraise(type(exc), exc, tb)\\n  File \\\"/Users/hamedbabaeian/MergedSkyNet/Backend/env/lib/python3.7/site-packages/vine/five.py\\\", line 195, in reraise\\n    raise value\\nFileNotFoundError: [Errno 2] No such file or directory\\n\"}, {\"time\": 1612259695, \"error_code\": 503, \"message\": \"Service down\", \"payload\": {\"payload\": \"[Errno 2] No such file or directory\"}, \"stack_trace\": \"Traceback (most recent call last):\\n  File \\\"/Users/hamedbabaeian/MergedSkyNet/Backend/core.py\\\", line 2023, in get_withdrawable_amount\\n    amount = _internal_task_manager.get_withdrawable_amount(user_id)\\n  File \\\"/Users/hamedbabaeian/MergedSkyNet/Backend/internal_task_manager.py\\\", line 274, in get_withdrawable_amount\\n    return {**amount_task_dump.get(), **amount_task.get()}\\n  File \\\"/Users/hamedbabaeian/MergedSkyNet/Backend/env/lib/python3.7/site-packages/celery/result.py\\\", line 211, in get\\n    self._maybe_reraise_parent_error()\\n  File \\\"/Users/hamedbabaeian/MergedSkyNet/Backend/env/lib/python3.7/site-packages/celery/result.py\\\", line 234, in _maybe_reraise_parent_error\\n    node.maybe_throw()\\n  File \\\"/Users/hamedbabaeian/MergedSkyNet/Backend/env/lib/python3.7/site-packages/celery/result.py\\\", line 333, in maybe_throw\\n    self.throw(value, self._to_remote_traceback(tb))\\n  File \\\"/Users/hamedbabaeian/MergedSkyNet/Backend/env/lib/python3.7/site-packages/celery/result.py\\\", line 326, in throw\\n    self.on_ready.throw(*args, **kwargs)\\n  File \\\"/Users/hamedbabaeian/MergedSkyNet/Backend/env/lib/python3.7/site-packages/vine/promises.py\\\", line 244, in throw\\n    reraise(type(exc), exc, tb)\\n  File \\\"/Users/hamedbabaeian/MergedSkyNet/Backend/env/lib/python3.7/site-packages/vine/five.py\\\", line 195, in reraise\\n    raise value\\nFileNotFoundError: [Errno 2] No such file or directory\\n\"}, {\"time\": 1612259695, \"error_code\": 503, \"message\": \"Service down\", \"payload\": {\"payload\": \"[Errno 2] No such file or directory\"}, \"stack_trace\": \"Traceback (most recent call last):\\n  File \\\"/Users/hamedbabaeian/MergedSkyNet/Backend/core.py\\\", line 2023, in get_withdrawable_amount\\n    amount = _internal_task_manager.get_withdrawable_amount(user_id)\\n  File \\\"/Users/hamedbabaeian/MergedSkyNet/Backend/internal_task_manager.py\\\", line 274, in get_withdrawable_amount\\n    return {**amount_task_dump.get(), **amount_task.get()}\\n  File \\\"/Users/hamedbabaeian/MergedSkyNet/Backend/env/lib/python3.7/site-packages/celery/result.py\\\", line 211, in get\\n    self._maybe_reraise_parent_error()\\n  File \\\"/Users/hamedbabaeian/MergedSkyNet/Backend/env/lib/python3.7/site-packages/celery/result.py\\\", line 234, in _maybe_reraise_parent_error\\n    node.maybe_throw()\\n  File \\\"/Users/hamedbabaeian/MergedSkyNet/Backend/env/lib/python3.7/site-packages/celery/result.py\\\", line 333, in maybe_throw\\n    self.throw(value, self._to_remote_traceback(tb))\\n  File \\\"/Users/hamedbabaeian/MergedSkyNet/Backend/env/lib/python3.7/site-packages/celery/result.py\\\", line 326, in throw\\n    self.on_ready.throw(*args, **kwargs)\\n  File \\\"/Users/hamedbabaeian/MergedSkyNet/Backend/env/lib/python3.7/site-packages/vine/promises.py\\\", line 244, in throw\\n    reraise(type(exc), exc, tb)\\n  File \\\"/Users/hamedbabaeian/MergedSkyNet/Backend/env/lib/python3.7/site-packages/vine/five.py\\\", line 195, in reraise\\n    raise value\\nFileNotFoundError: [Errno 2] No such file or directory\\n\"}, {\"time\": 1612259683, \"error_code\": 503, \"message\": \"Service down\", \"payload\": {\"payload\": \"[Errno 2] No such file or directory\"}, \"stack_trace\": \"Traceback (most recent call last):\\n  File \\\"/Users/hamedbabaeian/MergedSkyNet/Backend/core.py\\\", line 2023, in get_withdrawable_amount\\n    amount = _internal_task_manager.get_withdrawable_amount(user_id)\\n  File \\\"/Users/hamedbabaeian/MergedSkyNet/Backend/internal_task_manager.py\\\", line 274, in get_withdrawable_amount\\n    return {**amount_task_dump.get(), **amount_task.get()}\\n  File \\\"/Users/hamedbabaeian/MergedSkyNet/Backend/env/lib/python3.7/site-packages/celery/result.py\\\", line 211, in get\\n    self._maybe_reraise_parent_error()\\n  File \\\"/Users/hamedbabaeian/MergedSkyNet/Backend/env/lib/python3.7/site-packages/celery/result.py\\\", line 234, in _maybe_reraise_parent_error\\n    node.maybe_throw()\\n  File \\\"/Users/hamedbabaeian/MergedSkyNet/Backend/env/lib/python3.7/site-packages/celery/result.py\\\", line 333, in maybe_throw\\n    self.throw(value, self._to_remote_traceback(tb))\\n  File \\\"/Users/hamedbabaeian/MergedSkyNet/Backend/env/lib/python3.7/site-packages/celery/result.py\\\", line 326, in throw\\n    self.on_ready.throw(*args, **kwargs)\\n  File \\\"/Users/hamedbabaeian/MergedSkyNet/Backend/env/lib/python3.7/site-packages/vine/promises.py\\\", line 244, in throw\\n    reraise(type(exc), exc, tb)\\n  File \\\"/Users/hamedbabaeian/MergedSkyNet/Backend/env/lib/python3.7/site-packages/vine/five.py\\\", line 195, in reraise\\n    raise value\\nFileNotFoundError: [Errno 2] No such file or directory\\n\"}, {\"time\": 1612259682, \"error_code\": 503, \"message\": \"Service down\", \"payload\": {\"payload\": \"[Errno 2] No such file or directory\"}, \"stack_trace\": \"Traceback (most recent call last):\\n  File \\\"/Users/hamedbabaeian/MergedSkyNet/Backend/core.py\\\", line 2023, in get_withdrawable_amount\\n    amount = _internal_task_manager.get_withdrawable_amount(user_id)\\n  File \\\"/Users/hamedbabaeian/MergedSkyNet/Backend/internal_task_manager.py\\\", line 274, in get_withdrawable_amount\\n    return {**amount_task_dump.get(), **amount_task.get()}\\n  File \\\"/Users/hamedbabaeian/MergedSkyNet/Backend/env/lib/python3.7/site-packages/celery/result.py\\\", line 228, in get\\n    on_message=on_message,\\n  File \\\"/Users/hamedbabaeian/MergedSkyNet/Backend/env/lib/python3.7/site-packages/celery/backends/asynchronous.py\\\", line 200, in wait_for_pending\\n    for _ in self._wait_for_pending(result, **kwargs):\\n  File \\\"/Users/hamedbabaeian/MergedSkyNet/Backend/env/lib/python3.7/site-packages/celery/backends/asynchronous.py\\\", line 268, in _wait_for_pending\\n    on_interval=on_interval):\\n  File \\\"/Users/hamedbabaeian/MergedSkyNet/Backend/env/lib/python3.7/site-packages/celery/backends/asynchronous.py\\\", line 59, in drain_events_until\\n    on_interval()\\n  File \\\"/Users/hamedbabaeian/MergedSkyNet/Backend/env/lib/python3.7/site-packages/vine/promises.py\\\", line 170, in __call__\\n    return self.throw()\\n  File \\\"/Users/hamedbabaeian/MergedSkyNet/Backend/env/lib/python3.7/site-packages/vine/promises.py\\\", line 167, in __call__\\n    retval = fun(*final_args, **final_kwargs)\\n  File \\\"/Users/hamedbabaeian/MergedSkyNet/Backend/env/lib/python3.7/site-packages/celery/result.py\\\", line 234, in _maybe_reraise_parent_error\\n    node.maybe_throw()\\n  File \\\"/Users/hamedbabaeian/MergedSkyNet/Backend/env/lib/python3.7/site-packages/celery/result.py\\\", line 333, in maybe_throw\\n    self.throw(value, self._to_remote_traceback(tb))\\n  File \\\"/Users/hamedbabaeian/MergedSkyNet/Backend/env/lib/python3.7/site-packages/celery/result.py\\\", line 326, in throw\\n    self.on_ready.throw(*args, **kwargs)\\n  File \\\"/Users/hamedbabaeian/MergedSkyNet/Backend/env/lib/python3.7/site-packages/vine/promises.py\\\", line 244, in throw\\n    reraise(type(exc), exc, tb)\\n  File \\\"/Users/hamedbabaeian/MergedSkyNet/Backend/env/lib/python3.7/site-packages/vine/five.py\\\", line 195, in reraise\\n    raise value\\nFileNotFoundError: [Errno 2] No such file or directory\\n\"}, {\"time\": 1612259682, \"error_code\": 503, \"message\": \"Service down\", \"payload\": {\"payload\": \"[Errno 2] No such file or directory\"}, \"stack_trace\": \"Traceback (most recent call last):\\n  File \\\"/Users/hamedbabaeian/MergedSkyNet/Backend/core.py\\\", line 1059, in get_user_subscribed_strategies\\n    end=end)\\n  File \\\"/Users/hamedbabaeian/MergedSkyNet/Backend/internal_task_manager.py\\\", line 98, in get_user_subscribed_strategies\\n    args=(user_id, int(size), int(page), sort, order, begin, end), queue='strategies').get()\\n  File \\\"/Users/hamedbabaeian/MergedSkyNet/Backend/env/lib/python3.7/site-packages/celery/result.py\\\", line 228, in get\\n    on_message=on_message,\\n  File \\\"/Users/hamedbabaeian/MergedSkyNet/Backend/env/lib/python3.7/site-packages/celery/backends/asynchronous.py\\\", line 202, in wait_for_pending\\n    return result.maybe_throw(callback=callback, propagate=propagate)\\n  File \\\"/Users/hamedbabaeian/MergedSkyNet/Backend/env/lib/python3.7/site-packages/celery/result.py\\\", line 333, in maybe_throw\\n    self.throw(value, self._to_remote_traceback(tb))\\n  File \\\"/Users/hamedbabaeian/MergedSkyNet/Backend/env/lib/python3.7/site-packages/celery/result.py\\\", line 326, in throw\\n    self.on_ready.throw(*args, **kwargs)\\n  File \\\"/Users/hamedbabaeian/MergedSkyNet/Backend/env/lib/python3.7/site-packages/vine/promises.py\\\", line 244, in throw\\n    reraise(type(exc), exc, tb)\\n  File \\\"/Users/hamedbabaeian/MergedSkyNet/Backend/env/lib/python3.7/site-packages/vine/five.py\\\", line 195, in reraise\\n    raise value\\nFileNotFoundError: [Errno 2] No such file or directory\\n\"}, {\"time\": 1612259681, \"error_code\": 503, \"message\": \"Service down\", \"payload\": {\"payload\": \"[Errno 2] No such file or directory\"}, \"stack_trace\": \"Traceback (most recent call last):\\n  File \\\"/Users/hamedbabaeian/MergedSkyNet/Backend/core.py\\\", line 1059, in get_user_subscribed_strategies\\n    end=end)\\n  File \\\"/Users/hamedbabaeian/MergedSkyNet/Backend/internal_task_manager.py\\\", line 98, in get_user_subscribed_strategies\\n    args=(user_id, int(size), int(page), sort, order, begin, end), queue='strategies').get()\\n  File \\\"/Users/hamedbabaeian/MergedSkyNet/Backend/env/lib/python3.7/site-packages/celery/result.py\\\", line 228, in get\\n    on_message=on_message,\\n  File \\\"/Users/hamedbabaeian/MergedSkyNet/Backend/env/lib/python3.7/site-packages/celery/backends/asynchronous.py\\\", line 202, in wait_for_pending\\n    return result.maybe_throw(callback=callback, propagate=propagate)\\n  File \\\"/Users/hamedbabaeian/MergedSkyNet/Backend/env/lib/python3.7/site-packages/celery/result.py\\\", line 333, in maybe_throw\\n    self.throw(value, self._to_remote_traceback(tb))\\n  File \\\"/Users/hamedbabaeian/MergedSkyNet/Backend/env/lib/python3.7/site-packages/celery/result.py\\\", line 326, in throw\\n    self.on_ready.throw(*args, **kwargs)\\n  File \\\"/Users/hamedbabaeian/MergedSkyNet/Backend/env/lib/python3.7/site-packages/vine/promises.py\\\", line 244, in throw\\n    reraise(type(exc), exc, tb)\\n  File \\\"/Users/hamedbabaeian/MergedSkyNet/Backend/env/lib/python3.7/site-packages/vine/five.py\\\", line 195, in reraise\\n    raise value\\nFileNotFoundError: [Errno 2] No such file or directory\\n\"}, {\"time\": 1612258079, \"error_code\": 503, \"message\": \"Service down\", \"payload\": {\"payload\": \"[Errno 2] No such file or directory\"}, \"stack_trace\": \"Traceback (most recent call last):\\n  File \\\"/Users/hamedbabaeian/MergedSkyNet/Backend/core.py\\\", line 481, in get_user_count\\n    stats = _internal_task_manager.get_user_stats(begin, end)\\n  File \\\"/Users/hamedbabaeian/MergedSkyNet/Backend/internal_task_manager.py\\\", line 131, in get_user_stats\\n    for tr in customer_tasks.get(): content.extend(tr)\\n  File \\\"/Users/hamedbabaeian/MergedSkyNet/Backend/env/lib/python3.7/site-packages/celery/result.py\\\", line 703, in get\\n    on_interval=on_interval,\\n  File \\\"/Users/hamedbabaeian/MergedSkyNet/Backend/env/lib/python3.7/site-packages/celery/result.py\\\", line 830, in join_native\\n    raise value\\nFileNotFoundError: [Errno 2] No such file or directory\\n\"}, {\"time\": 1612257444, \"error_code\": 500, \"message\": \"Internal generic error\", \"payload\": {\"payload\": \"localhost:27017: [Errno 61] Connection refused\"}, \"stack_trace\": \"Traceback (most recent call last):\\n  File \\\"/Users/hamedbabaeian/MergedSkyNet/Backend/core.py\\\", line 1133, in login\\n    request.json.get('token', ''))\\n  File \\\"/Users/hamedbabaeian/MergedSkyNet/Backend/task_manager.py\\\", line 230, in login\\n    args=(username, password, token), queue='authentication').get()\\n  File \\\"/Users/hamedbabaeian/MergedSkyNet/Backend/env/lib/python3.7/site-packages/celery/result.py\\\", line 228, in get\\n    on_message=on_message,\\n  File \\\"/Users/hamedbabaeian/MergedSkyNet/Backend/env/lib/python3.7/site-packages/celery/backends/asynchronous.py\\\", line 202, in wait_for_pending\\n    return result.maybe_throw(callback=callback, propagate=propagate)\\n  File \\\"/Users/hamedbabaeian/MergedSkyNet/Backend/env/lib/python3.7/site-packages/celery/result.py\\\", line 333, in maybe_throw\\n    self.throw(value, self._to_remote_traceback(tb))\\n  File \\\"/Users/hamedbabaeian/MergedSkyNet/Backend/env/lib/python3.7/site-packages/celery/result.py\\\", line 326, in throw\\n    self.on_ready.throw(*args, **kwargs)\\n  File \\\"/Users/hamedbabaeian/MergedSkyNet/Backend/env/lib/python3.7/site-packages/vine/promises.py\\\", line 244, in throw\\n    reraise(type(exc), exc, tb)\\n  File \\\"/Users/hamedbabaeian/MergedSkyNet/Backend/env/lib/python3.7/site-packages/vine/five.py\\\", line 195, in reraise\\n    raise value\\npymongo.errors.ServerSelectionTimeoutError: localhost:27017: [Errno 61] Connection refused\\n\"}]")

    def test_get_diagnostics_mutation_0(self):
        task = diagnostics_service.get_diagnostics.s(
            None, None
        ).apply()
        self.assertEqual(task.result, "[{\"time\": 1612259842, \"error_code\": 503, \"message\": \"Service down\", \"payload\": {\"payload\": \"<module 'os' from '/Library/Developer/CommandLineTools/Library/Frameworks/Python3.framework/Versions/3.7/lib/python3.7/os.py'>\"}, \"stack_trace\": \"Traceback (most recent call last):\\n  File \\\"/Users/hamedbabaeian/MergedSkyNet/Backend/core.py\\\", line 1771, in get_active_strategy_names\\n    names = _internal_task_manager.get_active_strategy_names()\\n  File \\\"/Users/hamedbabaeian/MergedSkyNet/Backend/internal_task_manager.py\\\", line 62, in get_active_strategy_names\\n    return strategies_service.get_active_strategy_names.apply_async(queue='strategies').get()\\n  File \\\"/Users/hamedbabaeian/MergedSkyNet/Backend/env/lib/python3.7/site-packages/celery/result.py\\\", line 228, in get\\n    on_message=on_message,\\n  File \\\"/Users/hamedbabaeian/MergedSkyNet/Backend/env/lib/python3.7/site-packages/celery/backends/asynchronous.py\\\", line 202, in wait_for_pending\\n    return result.maybe_throw(callback=callback, propagate=propagate)\\n  File \\\"/Users/hamedbabaeian/MergedSkyNet/Backend/env/lib/python3.7/site-packages/celery/result.py\\\", line 333, in maybe_throw\\n    self.throw(value, self._to_remote_traceback(tb))\\n  File \\\"/Users/hamedbabaeian/MergedSkyNet/Backend/env/lib/python3.7/site-packages/celery/result.py\\\", line 326, in throw\\n    self.on_ready.throw(*args, **kwargs)\\n  File \\\"/Users/hamedbabaeian/MergedSkyNet/Backend/env/lib/python3.7/site-packages/vine/promises.py\\\", line 244, in throw\\n    reraise(type(exc), exc, tb)\\n  File \\\"/Users/hamedbabaeian/MergedSkyNet/Backend/env/lib/python3.7/site-packages/vine/five.py\\\", line 195, in reraise\\n    raise value\\nFileNotFoundError: [Errno 2] No such file or directory\\n\"}, {\"time\": 1612259841, \"error_code\": 503, \"message\": \"Service down\", \"payload\": {\"payload\": \"<module 'os' from '/Library/Developer/CommandLineTools/Library/Frameworks/Python3.framework/Versions/3.7/lib/python3.7/os.py'>\"}, \"stack_trace\": \"Traceback (most recent call last):\\n  File \\\"/Users/hamedbabaeian/MergedSkyNet/Backend/core.py\\\", line 1771, in get_active_strategy_names\\n    names = _internal_task_manager.get_active_strategy_names()\\n  File \\\"/Users/hamedbabaeian/MergedSkyNet/Backend/internal_task_manager.py\\\", line 62, in get_active_strategy_names\\n    return strategies_service.get_active_strategy_names.apply_async(queue='strategies').get()\\n  File \\\"/Users/hamedbabaeian/MergedSkyNet/Backend/env/lib/python3.7/site-packages/celery/result.py\\\", line 228, in get\\n    on_message=on_message,\\n  File \\\"/Users/hamedbabaeian/MergedSkyNet/Backend/env/lib/python3.7/site-packages/celery/backends/asynchronous.py\\\", line 202, in wait_for_pending\\n    return result.maybe_throw(callback=callback, propagate=propagate)\\n  File \\\"/Users/hamedbabaeian/MergedSkyNet/Backend/env/lib/python3.7/site-packages/celery/result.py\\\", line 333, in maybe_throw\\n    self.throw(value, self._to_remote_traceback(tb))\\n  File \\\"/Users/hamedbabaeian/MergedSkyNet/Backend/env/lib/python3.7/site-packages/celery/result.py\\\", line 326, in throw\\n    self.on_ready.throw(*args, **kwargs)\\n  File \\\"/Users/hamedbabaeian/MergedSkyNet/Backend/env/lib/python3.7/site-packages/vine/promises.py\\\", line 244, in throw\\n    reraise(type(exc), exc, tb)\\n  File \\\"/Users/hamedbabaeian/MergedSkyNet/Backend/env/lib/python3.7/site-packages/vine/five.py\\\", line 195, in reraise\\n    raise value\\nFileNotFoundError: [Errno 2] No such file or directory\\n\"}, {\"time\": 1612259818, \"error_code\": 503, \"message\": \"Service down\", \"payload\": {\"payload\": \"<module 'os' from '/Library/Developer/CommandLineTools/Library/Frameworks/Python3.framework/Versions/3.7/lib/python3.7/os.py'>\"}, \"stack_trace\": \"Traceback (most recent call last):\\n  File \\\"/Users/hamedbabaeian/MergedSkyNet/Backend/core.py\\\", line 1771, in get_active_strategy_names\\n    names = _internal_task_manager.get_active_strategy_names()\\n  File \\\"/Users/hamedbabaeian/MergedSkyNet/Backend/internal_task_manager.py\\\", line 62, in get_active_strategy_names\\n    return strategies_service.get_active_strategy_names.apply_async(queue='strategies').get()\\n  File \\\"/Users/hamedbabaeian/MergedSkyNet/Backend/env/lib/python3.7/site-packages/celery/result.py\\\", line 228, in get\\n    on_message=on_message,\\n  File \\\"/Users/hamedbabaeian/MergedSkyNet/Backend/env/lib/python3.7/site-packages/celery/backends/asynchronous.py\\\", line 202, in wait_for_pending\\n    return result.maybe_throw(callback=callback, propagate=propagate)\\n  File \\\"/Users/hamedbabaeian/MergedSkyNet/Backend/env/lib/python3.7/site-packages/celery/result.py\\\", line 333, in maybe_throw\\n    self.throw(value, self._to_remote_traceback(tb))\\n  File \\\"/Users/hamedbabaeian/MergedSkyNet/Backend/env/lib/python3.7/site-packages/celery/result.py\\\", line 326, in throw\\n    self.on_ready.throw(*args, **kwargs)\\n  File \\\"/Users/hamedbabaeian/MergedSkyNet/Backend/env/lib/python3.7/site-packages/vine/promises.py\\\", line 244, in throw\\n    reraise(type(exc), exc, tb)\\n  File \\\"/Users/hamedbabaeian/MergedSkyNet/Backend/env/lib/python3.7/site-packages/vine/five.py\\\", line 195, in reraise\\n    raise value\\nFileNotFoundError: [Errno 2] No such file or directory\\n\"}, {\"time\": 1612259817, \"error_code\": 503, \"message\": \"Service down\", \"payload\": {\"payload\": \"<module 'os' from '/Library/Developer/CommandLineTools/Library/Frameworks/Python3.framework/Versions/3.7/lib/python3.7/os.py'>\"}, \"stack_trace\": \"Traceback (most recent call last):\\n  File \\\"/Users/hamedbabaeian/MergedSkyNet/Backend/core.py\\\", line 1771, in get_active_strategy_names\\n    names = _internal_task_manager.get_active_strategy_names()\\n  File \\\"/Users/hamedbabaeian/MergedSkyNet/Backend/internal_task_manager.py\\\", line 62, in get_active_strategy_names\\n    return strategies_service.get_active_strategy_names.apply_async(queue='strategies').get()\\n  File \\\"/Users/hamedbabaeian/MergedSkyNet/Backend/env/lib/python3.7/site-packages/celery/result.py\\\", line 228, in get\\n    on_message=on_message,\\n  File \\\"/Users/hamedbabaeian/MergedSkyNet/Backend/env/lib/python3.7/site-packages/celery/backends/asynchronous.py\\\", line 202, in wait_for_pending\\n    return result.maybe_throw(callback=callback, propagate=propagate)\\n  File \\\"/Users/hamedbabaeian/MergedSkyNet/Backend/env/lib/python3.7/site-packages/celery/result.py\\\", line 333, in maybe_throw\\n    self.throw(value, self._to_remote_traceback(tb))\\n  File \\\"/Users/hamedbabaeian/MergedSkyNet/Backend/env/lib/python3.7/site-packages/celery/result.py\\\", line 326, in throw\\n    self.on_ready.throw(*args, **kwargs)\\n  File \\\"/Users/hamedbabaeian/MergedSkyNet/Backend/env/lib/python3.7/site-packages/vine/promises.py\\\", line 244, in throw\\n    reraise(type(exc), exc, tb)\\n  File \\\"/Users/hamedbabaeian/MergedSkyNet/Backend/env/lib/python3.7/site-packages/vine/five.py\\\", line 195, in reraise\\n    raise value\\nFileNotFoundError: [Errno 2] No such file or directory\\n\"}, {\"time\": 1612259791, \"error_code\": 503, \"message\": \"Service down\", \"payload\": {\"payload\": \"<module 'os' from '/Library/Developer/CommandLineTools/Library/Frameworks/Python3.framework/Versions/3.7/lib/python3.7/os.py'>\"}, \"stack_trace\": \"Traceback (most recent call last):\\n  File \\\"/Users/hamedbabaeian/MergedSkyNet/Backend/core.py\\\", line 1771, in get_active_strategy_names\\n    names = _internal_task_manager.get_active_strategy_names()\\n  File \\\"/Users/hamedbabaeian/MergedSkyNet/Backend/internal_task_manager.py\\\", line 62, in get_active_strategy_names\\n    return strategies_service.get_active_strategy_names.apply_async(queue='strategies').get()\\n  File \\\"/Users/hamedbabaeian/MergedSkyNet/Backend/env/lib/python3.7/site-packages/celery/result.py\\\", line 228, in get\\n    on_message=on_message,\\n  File \\\"/Users/hamedbabaeian/MergedSkyNet/Backend/env/lib/python3.7/site-packages/celery/backends/asynchronous.py\\\", line 202, in wait_for_pending\\n    return result.maybe_throw(callback=callback, propagate=propagate)\\n  File \\\"/Users/hamedbabaeian/MergedSkyNet/Backend/env/lib/python3.7/site-packages/celery/result.py\\\", line 333, in maybe_throw\\n    self.throw(value, self._to_remote_traceback(tb))\\n  File \\\"/Users/hamedbabaeian/MergedSkyNet/Backend/env/lib/python3.7/site-packages/celery/result.py\\\", line 326, in throw\\n    self.on_ready.throw(*args, **kwargs)\\n  File \\\"/Users/hamedbabaeian/MergedSkyNet/Backend/env/lib/python3.7/site-packages/vine/promises.py\\\", line 244, in throw\\n    reraise(type(exc), exc, tb)\\n  File \\\"/Users/hamedbabaeian/MergedSkyNet/Backend/env/lib/python3.7/site-packages/vine/five.py\\\", line 195, in reraise\\n    raise value\\nFileNotFoundError: [Errno 2] No such file or directory\\n\"}, {\"time\": 1612259790, \"error_code\": 503, \"message\": \"Service down\", \"payload\": {\"payload\": \"<module 'os' from '/Library/Developer/CommandLineTools/Library/Frameworks/Python3.framework/Versions/3.7/lib/python3.7/os.py'>\"}, \"stack_trace\": \"Traceback (most recent call last):\\n  File \\\"/Users/hamedbabaeian/MergedSkyNet/Backend/core.py\\\", line 1771, in get_active_strategy_names\\n    names = _internal_task_manager.get_active_strategy_names()\\n  File \\\"/Users/hamedbabaeian/MergedSkyNet/Backend/internal_task_manager.py\\\", line 62, in get_active_strategy_names\\n    return strategies_service.get_active_strategy_names.apply_async(queue='strategies').get()\\n  File \\\"/Users/hamedbabaeian/MergedSkyNet/Backend/env/lib/python3.7/site-packages/celery/result.py\\\", line 228, in get\\n    on_message=on_message,\\n  File \\\"/Users/hamedbabaeian/MergedSkyNet/Backend/env/lib/python3.7/site-packages/celery/backends/asynchronous.py\\\", line 202, in wait_for_pending\\n    return result.maybe_throw(callback=callback, propagate=propagate)\\n  File \\\"/Users/hamedbabaeian/MergedSkyNet/Backend/env/lib/python3.7/site-packages/celery/result.py\\\", line 333, in maybe_throw\\n    self.throw(value, self._to_remote_traceback(tb))\\n  File \\\"/Users/hamedbabaeian/MergedSkyNet/Backend/env/lib/python3.7/site-packages/celery/result.py\\\", line 326, in throw\\n    self.on_ready.throw(*args, **kwargs)\\n  File \\\"/Users/hamedbabaeian/MergedSkyNet/Backend/env/lib/python3.7/site-packages/vine/promises.py\\\", line 244, in throw\\n    reraise(type(exc), exc, tb)\\n  File \\\"/Users/hamedbabaeian/MergedSkyNet/Backend/env/lib/python3.7/site-packages/vine/five.py\\\", line 195, in reraise\\n    raise value\\nFileNotFoundError: [Errno 2] No such file or directory\\n\"}, {\"time\": 1612259713, \"error_code\": 503, \"message\": \"Service down\", \"payload\": {\"payload\": \"404 Client Error: Not Found for url: https://sandbox.swiftdil.com/v1/customers/TODO/documents\"}, \"stack_trace\": \"Traceback (most recent call last):\\n  File \\\"/Users/hamedbabaeian/MergedSkyNet/Backend/core.py\\\", line 845, in get_documents\\n    documents = _task_manager.get_documents(customer_id)\\n  File \\\"/Users/hamedbabaeian/MergedSkyNet/Backend/task_manager.py\\\", line 148, in get_documents\\n    args=(customer_id,), queue='file').get()\\n  File \\\"/Users/hamedbabaeian/MergedSkyNet/Backend/env/lib/python3.7/site-packages/celery/result.py\\\", line 228, in get\\n    on_message=on_message,\\n  File \\\"/Users/hamedbabaeian/MergedSkyNet/Backend/env/lib/python3.7/site-packages/celery/backends/asynchronous.py\\\", line 202, in wait_for_pending\\n    return result.maybe_throw(callback=callback, propagate=propagate)\\n  File \\\"/Users/hamedbabaeian/MergedSkyNet/Backend/env/lib/python3.7/site-packages/celery/result.py\\\", line 333, in maybe_throw\\n    self.throw(value, self._to_remote_traceback(tb))\\n  File \\\"/Users/hamedbabaeian/MergedSkyNet/Backend/env/lib/python3.7/site-packages/celery/result.py\\\", line 326, in throw\\n    self.on_ready.throw(*args, **kwargs)\\n  File \\\"/Users/hamedbabaeian/MergedSkyNet/Backend/env/lib/python3.7/site-packages/vine/promises.py\\\", line 244, in throw\\n    reraise(type(exc), exc, tb)\\n  File \\\"/Users/hamedbabaeian/MergedSkyNet/Backend/env/lib/python3.7/site-packages/vine/five.py\\\", line 195, in reraise\\n    raise value\\nrequests.exceptions.HTTPError: 404 Client Error: Not Found for url: https://sandbox.swiftdil.com/v1/customers/TODO/documents\\n\"}, {\"time\": 1612259713, \"error_code\": 503, \"message\": \"Service down\", \"payload\": {\"payload\": \"404 Client Error: Not Found for url: https://sandbox.swiftdil.com/v1/customers/TODO/screenings?size=20&page=0&sort=createdDate%2CDESC\"}, \"stack_trace\": \"Traceback (most recent call last):\\n  File \\\"/Users/hamedbabaeian/MergedSkyNet/Backend/core.py\\\", line 689, in get_screenings\\n    end=request.args.get('end', None))\\n  File \\\"/Users/hamedbabaeian/MergedSkyNet/Backend/task_manager.py\\\", line 99, in get_screenings\\n    created_after=begin, created_before=end).get()\\n  File \\\"/Users/hamedbabaeian/MergedSkyNet/Backend/env/lib/python3.7/site-packages/celery/result.py\\\", line 228, in get\\n    on_message=on_message,\\n  File \\\"/Users/hamedbabaeian/MergedSkyNet/Backend/env/lib/python3.7/site-packages/celery/backends/asynchronous.py\\\", line 202, in wait_for_pending\\n    return result.maybe_throw(callback=callback, propagate=propagate)\\n  File \\\"/Users/hamedbabaeian/MergedSkyNet/Backend/env/lib/python3.7/site-packages/celery/result.py\\\", line 333, in maybe_throw\\n    self.throw(value, self._to_remote_traceback(tb))\\n  File \\\"/Users/hamedbabaeian/MergedSkyNet/Backend/env/lib/python3.7/site-packages/celery/result.py\\\", line 326, in throw\\n    self.on_ready.throw(*args, **kwargs)\\n  File \\\"/Users/hamedbabaeian/MergedSkyNet/Backend/env/lib/python3.7/site-packages/vine/promises.py\\\", line 244, in throw\\n    reraise(type(exc), exc, tb)\\n  File \\\"/Users/hamedbabaeian/MergedSkyNet/Backend/env/lib/python3.7/site-packages/vine/five.py\\\", line 195, in reraise\\n    raise value\\nrequests.exceptions.HTTPError: 404 Client Error: Not Found for url: https://sandbox.swiftdil.com/v1/customers/TODO/screenings?size=20&page=0&sort=createdDate%2CDESC\\n\"}, {\"time\": 1612259712, \"error_code\": 503, \"message\": \"Service down\", \"payload\": {\"payload\": \"404 Client Error: Not Found for url: https://sandbox.swiftdil.com/v1/customers/TODO/risk_profile\"}, \"stack_trace\": \"Traceback (most recent call last):\\n  File \\\"/Users/hamedbabaeian/MergedSkyNet/Backend/core.py\\\", line 561, in get_customer_risk\\n    risk = _task_manager.get_customer_risk(customer_id)\\n  File \\\"/Users/hamedbabaeian/MergedSkyNet/Backend/task_manager.py\\\", line 49, in get_customer_risk\\n    args=(customer_id,), queue='customers').get()\\n  File \\\"/Users/hamedbabaeian/MergedSkyNet/Backend/env/lib/python3.7/site-packages/celery/result.py\\\", line 228, in get\\n    on_message=on_message,\\n  File \\\"/Users/hamedbabaeian/MergedSkyNet/Backend/env/lib/python3.7/site-packages/celery/backends/asynchronous.py\\\", line 202, in wait_for_pending\\n    return result.maybe_throw(callback=callback, propagate=propagate)\\n  File \\\"/Users/hamedbabaeian/MergedSkyNet/Backend/env/lib/python3.7/site-packages/celery/result.py\\\", line 333, in maybe_throw\\n    self.throw(value, self._to_remote_traceback(tb))\\n  File \\\"/Users/hamedbabaeian/MergedSkyNet/Backend/env/lib/python3.7/site-packages/celery/result.py\\\", line 326, in throw\\n    self.on_ready.throw(*args, **kwargs)\\n  File \\\"/Users/hamedbabaeian/MergedSkyNet/Backend/env/lib/python3.7/site-packages/vine/promises.py\\\", line 244, in throw\\n    reraise(type(exc), exc, tb)\\n  File \\\"/Users/hamedbabaeian/MergedSkyNet/Backend/env/lib/python3.7/site-packages/vine/five.py\\\", line 195, in reraise\\n    raise value\\nrequests.exceptions.HTTPError: 404 Client Error: Not Found for url: https://sandbox.swiftdil.com/v1/customers/TODO/risk_profile\\n\"}, {\"time\": 1612259711, \"error_code\": 503, \"message\": \"Service down\", \"payload\": {\"payload\": \"404 Client Error: Not Found for url: https://sandbox.swiftdil.com/v1/customers/TODO\"}, \"stack_trace\": \"Traceback (most recent call last):\\n  File \\\"/Users/hamedbabaeian/MergedSkyNet/Backend/core.py\\\", line 544, in get_customer\\n    customer = _task_manager.get_customer(customer_id)\\n  File \\\"/Users/hamedbabaeian/MergedSkyNet/Backend/task_manager.py\\\", line 45, in get_customer\\n    args=(customer_id,), queue='customers').get()\\n  File \\\"/Users/hamedbabaeian/MergedSkyNet/Backend/env/lib/python3.7/site-packages/celery/result.py\\\", line 228, in get\\n    on_message=on_message,\\n  File \\\"/Users/hamedbabaeian/MergedSkyNet/Backend/env/lib/python3.7/site-packages/celery/backends/asynchronous.py\\\", line 202, in wait_for_pending\\n    return result.maybe_throw(callback=callback, propagate=propagate)\\n  File \\\"/Users/hamedbabaeian/MergedSkyNet/Backend/env/lib/python3.7/site-packages/celery/result.py\\\", line 333, in maybe_throw\\n    self.throw(value, self._to_remote_traceback(tb))\\n  File \\\"/Users/hamedbabaeian/MergedSkyNet/Backend/env/lib/python3.7/site-packages/celery/result.py\\\", line 326, in throw\\n    self.on_ready.throw(*args, **kwargs)\\n  File \\\"/Users/hamedbabaeian/MergedSkyNet/Backend/env/lib/python3.7/site-packages/vine/promises.py\\\", line 244, in throw\\n    reraise(type(exc), exc, tb)\\n  File \\\"/Users/hamedbabaeian/MergedSkyNet/Backend/env/lib/python3.7/site-packages/vine/five.py\\\", line 195, in reraise\\n    raise value\\nrequests.exceptions.HTTPError: 404 Client Error: Not Found for url: https://sandbox.swiftdil.com/v1/customers/TODO\\n\"}, {\"time\": 1612259711, \"error_code\": 503, \"message\": \"Service down\", \"payload\": {\"payload\": \"404 Client Error: Not Found for url: https://sandbox.swiftdil.com/v1/customers/TODO/odd?size=7\"}, \"stack_trace\": \"Traceback (most recent call last):\\n  File \\\"/Users/hamedbabaeian/MergedSkyNet/Backend/core.py\\\", line 758, in get_odds\\n    request.args.get('end', None))\\n  File \\\"/Users/hamedbabaeian/MergedSkyNet/Backend/task_manager.py\\\", line 123, in get_odds\\n    created_before=end).get()\\n  File \\\"/Users/hamedbabaeian/MergedSkyNet/Backend/env/lib/python3.7/site-packages/celery/result.py\\\", line 228, in get\\n    on_message=on_message,\\n  File \\\"/Users/hamedbabaeian/MergedSkyNet/Backend/env/lib/python3.7/site-packages/celery/backends/asynchronous.py\\\", line 202, in wait_for_pending\\n    return result.maybe_throw(callback=callback, propagate=propagate)\\n  File \\\"/Users/hamedbabaeian/MergedSkyNet/Backend/env/lib/python3.7/site-packages/celery/result.py\\\", line 333, in maybe_throw\\n    self.throw(value, self._to_remote_traceback(tb))\\n  File \\\"/Users/hamedbabaeian/MergedSkyNet/Backend/env/lib/python3.7/site-packages/celery/result.py\\\", line 326, in throw\\n    self.on_ready.throw(*args, **kwargs)\\n  File \\\"/Users/hamedbabaeian/MergedSkyNet/Backend/env/lib/python3.7/site-packages/vine/promises.py\\\", line 244, in throw\\n    reraise(type(exc), exc, tb)\\n  File \\\"/Users/hamedbabaeian/MergedSkyNet/Backend/env/lib/python3.7/site-packages/vine/five.py\\\", line 195, in reraise\\n    raise value\\nrequests.exceptions.HTTPError: 404 Client Error: Not Found for url: https://sandbox.swiftdil.com/v1/customers/TODO/odd?size=7\\n\"}, {\"time\": 1612259711, \"error_code\": 503, \"message\": \"Service down\", \"payload\": {\"payload\": \"404 Client Error: Not Found for url: https://sandbox.swiftdil.com/v1/customers/TODO/screenings?size=20&page=0&sort=createdDate%2CDESC\"}, \"stack_trace\": \"Traceback (most recent call last):\\n  File \\\"/Users/hamedbabaeian/MergedSkyNet/Backend/core.py\\\", line 689, in get_screenings\\n    end=request.args.get('end', None))\\n  File \\\"/Users/hamedbabaeian/MergedSkyNet/Backend/task_manager.py\\\", line 99, in get_screenings\\n    created_after=begin, created_before=end).get()\\n  File \\\"/Users/hamedbabaeian/MergedSkyNet/Backend/env/lib/python3.7/site-packages/celery/result.py\\\", line 228, in get\\n    on_message=on_message,\\n  File \\\"/Users/hamedbabaeian/MergedSkyNet/Backend/env/lib/python3.7/site-packages/celery/backends/asynchronous.py\\\", line 202, in wait_for_pending\\n    return result.maybe_throw(callback=callback, propagate=propagate)\\n  File \\\"/Users/hamedbabaeian/MergedSkyNet/Backend/env/lib/python3.7/site-packages/celery/result.py\\\", line 333, in maybe_throw\\n    self.throw(value, self._to_remote_traceback(tb))\\n  File \\\"/Users/hamedbabaeian/MergedSkyNet/Backend/env/lib/python3.7/site-packages/celery/result.py\\\", line 326, in throw\\n    self.on_ready.throw(*args, **kwargs)\\n  File \\\"/Users/hamedbabaeian/MergedSkyNet/Backend/env/lib/python3.7/site-packages/vine/promises.py\\\", line 244, in throw\\n    reraise(type(exc), exc, tb)\\n  File \\\"/Users/hamedbabaeian/MergedSkyNet/Backend/env/lib/python3.7/site-packages/vine/five.py\\\", line 195, in reraise\\n    raise value\\nrequests.exceptions.HTTPError: 404 Client Error: Not Found for url: https://sandbox.swiftdil.com/v1/customers/TODO/screenings?size=20&page=0&sort=createdDate%2CDESC\\n\"}, {\"time\": 1612259711, \"error_code\": 503, \"message\": \"Service down\", \"payload\": {\"payload\": \"404 Client Error: Not Found for url: https://sandbox.swiftdil.com/v1/customers/TODO/documents\"}, \"stack_trace\": \"Traceback (most recent call last):\\n  File \\\"/Users/hamedbabaeian/MergedSkyNet/Backend/core.py\\\", line 845, in get_documents\\n    documents = _task_manager.get_documents(customer_id)\\n  File \\\"/Users/hamedbabaeian/MergedSkyNet/Backend/task_manager.py\\\", line 148, in get_documents\\n    args=(customer_id,), queue='file').get()\\n  File \\\"/Users/hamedbabaeian/MergedSkyNet/Backend/env/lib/python3.7/site-packages/celery/result.py\\\", line 228, in get\\n    on_message=on_message,\\n  File \\\"/Users/hamedbabaeian/MergedSkyNet/Backend/env/lib/python3.7/site-packages/celery/backends/asynchronous.py\\\", line 202, in wait_for_pending\\n    return result.maybe_throw(callback=callback, propagate=propagate)\\n  File \\\"/Users/hamedbabaeian/MergedSkyNet/Backend/env/lib/python3.7/site-packages/celery/result.py\\\", line 333, in maybe_throw\\n    self.throw(value, self._to_remote_traceback(tb))\\n  File \\\"/Users/hamedbabaeian/MergedSkyNet/Backend/env/lib/python3.7/site-packages/celery/result.py\\\", line 326, in throw\\n    self.on_ready.throw(*args, **kwargs)\\n  File \\\"/Users/hamedbabaeian/MergedSkyNet/Backend/env/lib/python3.7/site-packages/vine/promises.py\\\", line 244, in throw\\n    reraise(type(exc), exc, tb)\\n  File \\\"/Users/hamedbabaeian/MergedSkyNet/Backend/env/lib/python3.7/site-packages/vine/five.py\\\", line 195, in reraise\\n    raise value\\nrequests.exceptions.HTTPError: 404 Client Error: Not Found for url: https://sandbox.swiftdil.com/v1/customers/TODO/documents\\n\"}, {\"time\": 1612259710, \"error_code\": 503, \"message\": \"Service down\", \"payload\": {\"payload\": \"404 Client Error: Not Found for url: https://sandbox.swiftdil.com/v1/customers/TODO/risk_profile\"}, \"stack_trace\": \"Traceback (most recent call last):\\n  File \\\"/Users/hamedbabaeian/MergedSkyNet/Backend/core.py\\\", line 561, in get_customer_risk\\n    risk = _task_manager.get_customer_risk(customer_id)\\n  File \\\"/Users/hamedbabaeian/MergedSkyNet/Backend/task_manager.py\\\", line 49, in get_customer_risk\\n    args=(customer_id,), queue='customers').get()\\n  File \\\"/Users/hamedbabaeian/MergedSkyNet/Backend/env/lib/python3.7/site-packages/celery/result.py\\\", line 228, in get\\n    on_message=on_message,\\n  File \\\"/Users/hamedbabaeian/MergedSkyNet/Backend/env/lib/python3.7/site-packages/celery/backends/asynchronous.py\\\", line 202, in wait_for_pending\\n    return result.maybe_throw(callback=callback, propagate=propagate)\\n  File \\\"/Users/hamedbabaeian/MergedSkyNet/Backend/env/lib/python3.7/site-packages/celery/result.py\\\", line 333, in maybe_throw\\n    self.throw(value, self._to_remote_traceback(tb))\\n  File \\\"/Users/hamedbabaeian/MergedSkyNet/Backend/env/lib/python3.7/site-packages/celery/result.py\\\", line 326, in throw\\n    self.on_ready.throw(*args, **kwargs)\\n  File \\\"/Users/hamedbabaeian/MergedSkyNet/Backend/env/lib/python3.7/site-packages/vine/promises.py\\\", line 244, in throw\\n    reraise(type(exc), exc, tb)\\n  File \\\"/Users/hamedbabaeian/MergedSkyNet/Backend/env/lib/python3.7/site-packages/vine/five.py\\\", line 195, in reraise\\n    raise value\\nrequests.exceptions.HTTPError: 404 Client Error: Not Found for url: https://sandbox.swiftdil.com/v1/customers/TODO/risk_profile\\n\"}, {\"time\": 1612259710, \"error_code\": 503, \"message\": \"Service down\", \"payload\": {\"payload\": \"404 Client Error: Not Found for url: https://sandbox.swiftdil.com/v1/customers/TODO\"}, \"stack_trace\": \"Traceback (most recent call last):\\n  File \\\"/Users/hamedbabaeian/MergedSkyNet/Backend/core.py\\\", line 544, in get_customer\\n    customer = _task_manager.get_customer(customer_id)\\n  File \\\"/Users/hamedbabaeian/MergedSkyNet/Backend/task_manager.py\\\", line 45, in get_customer\\n    args=(customer_id,), queue='customers').get()\\n  File \\\"/Users/hamedbabaeian/MergedSkyNet/Backend/env/lib/python3.7/site-packages/celery/result.py\\\", line 228, in get\\n    on_message=on_message,\\n  File \\\"/Users/hamedbabaeian/MergedSkyNet/Backend/env/lib/python3.7/site-packages/celery/backends/asynchronous.py\\\", line 202, in wait_for_pending\\n    return result.maybe_throw(callback=callback, propagate=propagate)\\n  File \\\"/Users/hamedbabaeian/MergedSkyNet/Backend/env/lib/python3.7/site-packages/celery/result.py\\\", line 333, in maybe_throw\\n    self.throw(value, self._to_remote_traceback(tb))\\n  File \\\"/Users/hamedbabaeian/MergedSkyNet/Backend/env/lib/python3.7/site-packages/celery/result.py\\\", line 326, in throw\\n    self.on_ready.throw(*args, **kwargs)\\n  File \\\"/Users/hamedbabaeian/MergedSkyNet/Backend/env/lib/python3.7/site-packages/vine/promises.py\\\", line 244, in throw\\n    reraise(type(exc), exc, tb)\\n  File \\\"/Users/hamedbabaeian/MergedSkyNet/Backend/env/lib/python3.7/site-packages/vine/five.py\\\", line 195, in reraise\\n    raise value\\nrequests.exceptions.HTTPError: 404 Client Error: Not Found for url: https://sandbox.swiftdil.com/v1/customers/TODO\\n\"}, {\"time\": 1612259710, \"error_code\": 503, \"message\": \"Service down\", \"payload\": {\"payload\": \"404 Client Error: Not Found for url: https://sandbox.swiftdil.com/v1/customers/TODO/odd?size=7\"}, \"stack_trace\": \"Traceback (most recent call last):\\n  File \\\"/Users/hamedbabaeian/MergedSkyNet/Backend/core.py\\\", line 758, in get_odds\\n    request.args.get('end', None))\\n  File \\\"/Users/hamedbabaeian/MergedSkyNet/Backend/task_manager.py\\\", line 123, in get_odds\\n    created_before=end).get()\\n  File \\\"/Users/hamedbabaeian/MergedSkyNet/Backend/env/lib/python3.7/site-packages/celery/result.py\\\", line 228, in get\\n    on_message=on_message,\\n  File \\\"/Users/hamedbabaeian/MergedSkyNet/Backend/env/lib/python3.7/site-packages/celery/backends/asynchronous.py\\\", line 202, in wait_for_pending\\n    return result.maybe_throw(callback=callback, propagate=propagate)\\n  File \\\"/Users/hamedbabaeian/MergedSkyNet/Backend/env/lib/python3.7/site-packages/celery/result.py\\\", line 333, in maybe_throw\\n    self.throw(value, self._to_remote_traceback(tb))\\n  File \\\"/Users/hamedbabaeian/MergedSkyNet/Backend/env/lib/python3.7/site-packages/celery/result.py\\\", line 326, in throw\\n    self.on_ready.throw(*args, **kwargs)\\n  File \\\"/Users/hamedbabaeian/MergedSkyNet/Backend/env/lib/python3.7/site-packages/vine/promises.py\\\", line 244, in throw\\n    reraise(type(exc), exc, tb)\\n  File \\\"/Users/hamedbabaeian/MergedSkyNet/Backend/env/lib/python3.7/site-packages/vine/five.py\\\", line 195, in reraise\\n    raise value\\nrequests.exceptions.HTTPError: 404 Client Error: Not Found for url: https://sandbox.swiftdil.com/v1/customers/TODO/odd?size=7\\n\"}, {\"time\": 1612259710, \"error_code\": 503, \"message\": \"Service down\", \"payload\": {\"payload\": \"[Errno 2] No such file or directory\"}, \"stack_trace\": \"Traceback (most recent call last):\\n  File \\\"/Users/hamedbabaeian/MergedSkyNet/Backend/core.py\\\", line 2023, in get_withdrawable_amount\\n    amount = _internal_task_manager.get_withdrawable_amount(user_id)\\n  File \\\"/Users/hamedbabaeian/MergedSkyNet/Backend/internal_task_manager.py\\\", line 274, in get_withdrawable_amount\\n    return {**amount_task_dump.get(), **amount_task.get()}\\n  File \\\"/Users/hamedbabaeian/MergedSkyNet/Backend/env/lib/python3.7/site-packages/celery/result.py\\\", line 211, in get\\n    self._maybe_reraise_parent_error()\\n  File \\\"/Users/hamedbabaeian/MergedSkyNet/Backend/env/lib/python3.7/site-packages/celery/result.py\\\", line 234, in _maybe_reraise_parent_error\\n    node.maybe_throw()\\n  File \\\"/Users/hamedbabaeian/MergedSkyNet/Backend/env/lib/python3.7/site-packages/celery/result.py\\\", line 333, in maybe_throw\\n    self.throw(value, self._to_remote_traceback(tb))\\n  File \\\"/Users/hamedbabaeian/MergedSkyNet/Backend/env/lib/python3.7/site-packages/celery/result.py\\\", line 326, in throw\\n    self.on_ready.throw(*args, **kwargs)\\n  File \\\"/Users/hamedbabaeian/MergedSkyNet/Backend/env/lib/python3.7/site-packages/vine/promises.py\\\", line 244, in throw\\n    reraise(type(exc), exc, tb)\\n  File \\\"/Users/hamedbabaeian/MergedSkyNet/Backend/env/lib/python3.7/site-packages/vine/five.py\\\", line 195, in reraise\\n    raise value\\nFileNotFoundError: [Errno 2] No such file or directory\\n\"}, {\"time\": 1612259709, \"error_code\": 503, \"message\": \"Service down\", \"payload\": {\"payload\": \"[Errno 2] No such file or directory\"}, \"stack_trace\": \"Traceback (most recent call last):\\n  File \\\"/Users/hamedbabaeian/MergedSkyNet/Backend/core.py\\\", line 352, in get_user_timeline\\n    result = _internal_task_manager.get_user_timeline(user_id)\\n  File \\\"/Users/hamedbabaeian/MergedSkyNet/Backend/internal_task_manager.py\\\", line 243, in get_user_timeline\\n    for sb in subscription_tasks.get(): result.extend(json.loads(sb))\\n  File \\\"/Users/hamedbabaeian/MergedSkyNet/Backend/env/lib/python3.7/site-packages/celery/result.py\\\", line 703, in get\\n    on_interval=on_interval,\\n  File \\\"/Users/hamedbabaeian/MergedSkyNet/Backend/env/lib/python3.7/site-packages/celery/result.py\\\", line 830, in join_native\\n    raise value\\nFileNotFoundError: [Errno 2] No such file or directory\\n\"}, {\"time\": 1612259707, \"error_code\": 503, \"message\": \"Service down\", \"payload\": {\"payload\": \"[Errno 2] No such file or directory\"}, \"stack_trace\": \"Traceback (most recent call last):\\n  File \\\"/Users/hamedbabaeian/MergedSkyNet/Backend/core.py\\\", line 1059, in get_user_subscribed_strategies\\n    end=end)\\n  File \\\"/Users/hamedbabaeian/MergedSkyNet/Backend/internal_task_manager.py\\\", line 98, in get_user_subscribed_strategies\\n    args=(user_id, int(size), int(page), sort, order, begin, end), queue='strategies').get()\\n  File \\\"/Users/hamedbabaeian/MergedSkyNet/Backend/env/lib/python3.7/site-packages/celery/result.py\\\", line 228, in get\\n    on_message=on_message,\\n  File \\\"/Users/hamedbabaeian/MergedSkyNet/Backend/env/lib/python3.7/site-packages/celery/backends/asynchronous.py\\\", line 202, in wait_for_pending\\n    return result.maybe_throw(callback=callback, propagate=propagate)\\n  File \\\"/Users/hamedbabaeian/MergedSkyNet/Backend/env/lib/python3.7/site-packages/celery/result.py\\\", line 333, in maybe_throw\\n    self.throw(value, self._to_remote_traceback(tb))\\n  File \\\"/Users/hamedbabaeian/MergedSkyNet/Backend/env/lib/python3.7/site-packages/celery/result.py\\\", line 326, in throw\\n    self.on_ready.throw(*args, **kwargs)\\n  File \\\"/Users/hamedbabaeian/MergedSkyNet/Backend/env/lib/python3.7/site-packages/vine/promises.py\\\", line 244, in throw\\n    reraise(type(exc), exc, tb)\\n  File \\\"/Users/hamedbabaeian/MergedSkyNet/Backend/env/lib/python3.7/site-packages/vine/five.py\\\", line 195, in reraise\\n    raise value\\nFileNotFoundError: [Errno 2] No such file or directory\\n\"}, {\"time\": 1612259707, \"error_code\": 503, \"message\": \"Service down\", \"payload\": {\"payload\": \"[Errno 2] No such file or directory\"}, \"stack_trace\": \"Traceback (most recent call last):\\n  File \\\"/Users/hamedbabaeian/MergedSkyNet/Backend/core.py\\\", line 1088, in get_user_unsubscribed_strategies\\n    end=end)\\n  File \\\"/Users/hamedbabaeian/MergedSkyNet/Backend/internal_task_manager.py\\\", line 103, in get_user_unsubscribed_strategies\\n    args=(user_id, int(size), int(page), sort, order, begin, end), queue='strategies').get()\\n  File \\\"/Users/hamedbabaeian/MergedSkyNet/Backend/env/lib/python3.7/site-packages/celery/result.py\\\", line 228, in get\\n    on_message=on_message,\\n  File \\\"/Users/hamedbabaeian/MergedSkyNet/Backend/env/lib/python3.7/site-packages/celery/backends/asynchronous.py\\\", line 202, in wait_for_pending\\n    return result.maybe_throw(callback=callback, propagate=propagate)\\n  File \\\"/Users/hamedbabaeian/MergedSkyNet/Backend/env/lib/python3.7/site-packages/celery/result.py\\\", line 333, in maybe_throw\\n    self.throw(value, self._to_remote_traceback(tb))\\n  File \\\"/Users/hamedbabaeian/MergedSkyNet/Backend/env/lib/python3.7/site-packages/celery/result.py\\\", line 326, in throw\\n    self.on_ready.throw(*args, **kwargs)\\n  File \\\"/Users/hamedbabaeian/MergedSkyNet/Backend/env/lib/python3.7/site-packages/vine/promises.py\\\", line 244, in throw\\n    reraise(type(exc), exc, tb)\\n  File \\\"/Users/hamedbabaeian/MergedSkyNet/Backend/env/lib/python3.7/site-packages/vine/five.py\\\", line 195, in reraise\\n    raise value\\nFileNotFoundError: [Errno 2] No such file or directory\\n\"}, {\"time\": 1612259707, \"error_code\": 503, \"message\": \"Service down\", \"payload\": {\"payload\": \"[Errno 2] No such file or directory\"}, \"stack_trace\": \"Traceback (most recent call last):\\n  File \\\"/Users/hamedbabaeian/MergedSkyNet/Backend/core.py\\\", line 2023, in get_withdrawable_amount\\n    amount = _internal_task_manager.get_withdrawable_amount(user_id)\\n  File \\\"/Users/hamedbabaeian/MergedSkyNet/Backend/internal_task_manager.py\\\", line 274, in get_withdrawable_amount\\n    return {**amount_task_dump.get(), **amount_task.get()}\\n  File \\\"/Users/hamedbabaeian/MergedSkyNet/Backend/env/lib/python3.7/site-packages/celery/result.py\\\", line 211, in get\\n    self._maybe_reraise_parent_error()\\n  File \\\"/Users/hamedbabaeian/MergedSkyNet/Backend/env/lib/python3.7/site-packages/celery/result.py\\\", line 234, in _maybe_reraise_parent_error\\n    node.maybe_throw()\\n  File \\\"/Users/hamedbabaeian/MergedSkyNet/Backend/env/lib/python3.7/site-packages/celery/result.py\\\", line 333, in maybe_throw\\n    self.throw(value, self._to_remote_traceback(tb))\\n  File \\\"/Users/hamedbabaeian/MergedSkyNet/Backend/env/lib/python3.7/site-packages/celery/result.py\\\", line 326, in throw\\n    self.on_ready.throw(*args, **kwargs)\\n  File \\\"/Users/hamedbabaeian/MergedSkyNet/Backend/env/lib/python3.7/site-packages/vine/promises.py\\\", line 244, in throw\\n    reraise(type(exc), exc, tb)\\n  File \\\"/Users/hamedbabaeian/MergedSkyNet/Backend/env/lib/python3.7/site-packages/vine/five.py\\\", line 195, in reraise\\n    raise value\\nFileNotFoundError: [Errno 2] No such file or directory\\n\"}, {\"time\": 1612259707, \"error_code\": 503, \"message\": \"Service down\", \"payload\": {\"payload\": \"[Errno 2] No such file or directory\"}, \"stack_trace\": \"Traceback (most recent call last):\\n  File \\\"/Users/hamedbabaeian/MergedSkyNet/Backend/core.py\\\", line 352, in get_user_timeline\\n    result = _internal_task_manager.get_user_timeline(user_id)\\n  File \\\"/Users/hamedbabaeian/MergedSkyNet/Backend/internal_task_manager.py\\\", line 243, in get_user_timeline\\n    for sb in subscription_tasks.get(): result.extend(json.loads(sb))\\n  File \\\"/Users/hamedbabaeian/MergedSkyNet/Backend/env/lib/python3.7/site-packages/celery/result.py\\\", line 703, in get\\n    on_interval=on_interval,\\n  File \\\"/Users/hamedbabaeian/MergedSkyNet/Backend/env/lib/python3.7/site-packages/celery/result.py\\\", line 830, in join_native\\n    raise value\\nFileNotFoundError: [Errno 2] No such file or directory\\n\"}, {\"time\": 1612259706, \"error_code\": 503, \"message\": \"Service down\", \"payload\": {\"payload\": \"[Errno 2] No such file or directory\"}, \"stack_trace\": \"Traceback (most recent call last):\\n  File \\\"/Users/hamedbabaeian/MergedSkyNet/Backend/core.py\\\", line 1059, in get_user_subscribed_strategies\\n    end=end)\\n  File \\\"/Users/hamedbabaeian/MergedSkyNet/Backend/internal_task_manager.py\\\", line 98, in get_user_subscribed_strategies\\n    args=(user_id, int(size), int(page), sort, order, begin, end), queue='strategies').get()\\n  File \\\"/Users/hamedbabaeian/MergedSkyNet/Backend/env/lib/python3.7/site-packages/celery/result.py\\\", line 228, in get\\n    on_message=on_message,\\n  File \\\"/Users/hamedbabaeian/MergedSkyNet/Backend/env/lib/python3.7/site-packages/celery/backends/asynchronous.py\\\", line 202, in wait_for_pending\\n    return result.maybe_throw(callback=callback, propagate=propagate)\\n  File \\\"/Users/hamedbabaeian/MergedSkyNet/Backend/env/lib/python3.7/site-packages/celery/result.py\\\", line 333, in maybe_throw\\n    self.throw(value, self._to_remote_traceback(tb))\\n  File \\\"/Users/hamedbabaeian/MergedSkyNet/Backend/env/lib/python3.7/site-packages/celery/result.py\\\", line 326, in throw\\n    self.on_ready.throw(*args, **kwargs)\\n  File \\\"/Users/hamedbabaeian/MergedSkyNet/Backend/env/lib/python3.7/site-packages/vine/promises.py\\\", line 244, in throw\\n    reraise(type(exc), exc, tb)\\n  File \\\"/Users/hamedbabaeian/MergedSkyNet/Backend/env/lib/python3.7/site-packages/vine/five.py\\\", line 195, in reraise\\n    raise value\\nFileNotFoundError: [Errno 2] No such file or directory\\n\"}, {\"time\": 1612259706, \"error_code\": 503, \"message\": \"Service down\", \"payload\": {\"payload\": \"[Errno 2] No such file or directory\"}, \"stack_trace\": \"Traceback (most recent call last):\\n  File \\\"/Users/hamedbabaeian/MergedSkyNet/Backend/core.py\\\", line 1088, in get_user_unsubscribed_strategies\\n    end=end)\\n  File \\\"/Users/hamedbabaeian/MergedSkyNet/Backend/internal_task_manager.py\\\", line 103, in get_user_unsubscribed_strategies\\n    args=(user_id, int(size), int(page), sort, order, begin, end), queue='strategies').get()\\n  File \\\"/Users/hamedbabaeian/MergedSkyNet/Backend/env/lib/python3.7/site-packages/celery/result.py\\\", line 228, in get\\n    on_message=on_message,\\n  File \\\"/Users/hamedbabaeian/MergedSkyNet/Backend/env/lib/python3.7/site-packages/celery/backends/asynchronous.py\\\", line 202, in wait_for_pending\\n    return result.maybe_throw(callback=callback, propagate=propagate)\\n  File \\\"/Users/hamedbabaeian/MergedSkyNet/Backend/env/lib/python3.7/site-packages/celery/result.py\\\", line 333, in maybe_throw\\n    self.throw(value, self._to_remote_traceback(tb))\\n  File \\\"/Users/hamedbabaeian/MergedSkyNet/Backend/env/lib/python3.7/site-packages/celery/result.py\\\", line 326, in throw\\n    self.on_ready.throw(*args, **kwargs)\\n  File \\\"/Users/hamedbabaeian/MergedSkyNet/Backend/env/lib/python3.7/site-packages/vine/promises.py\\\", line 244, in throw\\n    reraise(type(exc), exc, tb)\\n  File \\\"/Users/hamedbabaeian/MergedSkyNet/Backend/env/lib/python3.7/site-packages/vine/five.py\\\", line 195, in reraise\\n    raise value\\nFileNotFoundError: [Errno 2] No such file or directory\\n\"}, {\"time\": 1612259697, \"error_code\": 503, \"message\": \"Service down\", \"payload\": {\"payload\": \"[Errno 2] No such file or directory\"}, \"stack_trace\": \"Traceback (most recent call last):\\n  File \\\"/Users/hamedbabaeian/MergedSkyNet/Backend/core.py\\\", line 1059, in get_user_subscribed_strategies\\n    end=end)\\n  File \\\"/Users/hamedbabaeian/MergedSkyNet/Backend/internal_task_manager.py\\\", line 98, in get_user_subscribed_strategies\\n    args=(user_id, int(size), int(page), sort, order, begin, end), queue='strategies').get()\\n  File \\\"/Users/hamedbabaeian/MergedSkyNet/Backend/env/lib/python3.7/site-packages/celery/result.py\\\", line 228, in get\\n    on_message=on_message,\\n  File \\\"/Users/hamedbabaeian/MergedSkyNet/Backend/env/lib/python3.7/site-packages/celery/backends/asynchronous.py\\\", line 202, in wait_for_pending\\n    return result.maybe_throw(callback=callback, propagate=propagate)\\n  File \\\"/Users/hamedbabaeian/MergedSkyNet/Backend/env/lib/python3.7/site-packages/celery/result.py\\\", line 333, in maybe_throw\\n    self.throw(value, self._to_remote_traceback(tb))\\n  File \\\"/Users/hamedbabaeian/MergedSkyNet/Backend/env/lib/python3.7/site-packages/celery/result.py\\\", line 326, in throw\\n    self.on_ready.throw(*args, **kwargs)\\n  File \\\"/Users/hamedbabaeian/MergedSkyNet/Backend/env/lib/python3.7/site-packages/vine/promises.py\\\", line 244, in throw\\n    reraise(type(exc), exc, tb)\\n  File \\\"/Users/hamedbabaeian/MergedSkyNet/Backend/env/lib/python3.7/site-packages/vine/five.py\\\", line 195, in reraise\\n    raise value\\nFileNotFoundError: [Errno 2] No such file or directory\\n\"}, {\"time\": 1612259696, \"error_code\": 503, \"message\": \"Service down\", \"payload\": {\"payload\": \"[Errno 2] No such file or directory\"}, \"stack_trace\": \"Traceback (most recent call last):\\n  File \\\"/Users/hamedbabaeian/MergedSkyNet/Backend/core.py\\\", line 1059, in get_user_subscribed_strategies\\n    end=end)\\n  File \\\"/Users/hamedbabaeian/MergedSkyNet/Backend/internal_task_manager.py\\\", line 98, in get_user_subscribed_strategies\\n    args=(user_id, int(size), int(page), sort, order, begin, end), queue='strategies').get()\\n  File \\\"/Users/hamedbabaeian/MergedSkyNet/Backend/env/lib/python3.7/site-packages/celery/result.py\\\", line 228, in get\\n    on_message=on_message,\\n  File \\\"/Users/hamedbabaeian/MergedSkyNet/Backend/env/lib/python3.7/site-packages/celery/backends/asynchronous.py\\\", line 202, in wait_for_pending\\n    return result.maybe_throw(callback=callback, propagate=propagate)\\n  File \\\"/Users/hamedbabaeian/MergedSkyNet/Backend/env/lib/python3.7/site-packages/celery/result.py\\\", line 333, in maybe_throw\\n    self.throw(value, self._to_remote_traceback(tb))\\n  File \\\"/Users/hamedbabaeian/MergedSkyNet/Backend/env/lib/python3.7/site-packages/celery/result.py\\\", line 326, in throw\\n    self.on_ready.throw(*args, **kwargs)\\n  File \\\"/Users/hamedbabaeian/MergedSkyNet/Backend/env/lib/python3.7/site-packages/vine/promises.py\\\", line 244, in throw\\n    reraise(type(exc), exc, tb)\\n  File \\\"/Users/hamedbabaeian/MergedSkyNet/Backend/env/lib/python3.7/site-packages/vine/five.py\\\", line 195, in reraise\\n    raise value\\nFileNotFoundError: [Errno 2] No such file or directory\\n\"}, {\"time\": 1612259695, \"error_code\": 503, \"message\": \"Service down\", \"payload\": {\"payload\": \"[Errno 2] No such file or directory\"}, \"stack_trace\": \"Traceback (most recent call last):\\n  File \\\"/Users/hamedbabaeian/MergedSkyNet/Backend/core.py\\\", line 2023, in get_withdrawable_amount\\n    amount = _internal_task_manager.get_withdrawable_amount(user_id)\\n  File \\\"/Users/hamedbabaeian/MergedSkyNet/Backend/internal_task_manager.py\\\", line 274, in get_withdrawable_amount\\n    return {**amount_task_dump.get(), **amount_task.get()}\\n  File \\\"/Users/hamedbabaeian/MergedSkyNet/Backend/env/lib/python3.7/site-packages/celery/result.py\\\", line 211, in get\\n    self._maybe_reraise_parent_error()\\n  File \\\"/Users/hamedbabaeian/MergedSkyNet/Backend/env/lib/python3.7/site-packages/celery/result.py\\\", line 234, in _maybe_reraise_parent_error\\n    node.maybe_throw()\\n  File \\\"/Users/hamedbabaeian/MergedSkyNet/Backend/env/lib/python3.7/site-packages/celery/result.py\\\", line 333, in maybe_throw\\n    self.throw(value, self._to_remote_traceback(tb))\\n  File \\\"/Users/hamedbabaeian/MergedSkyNet/Backend/env/lib/python3.7/site-packages/celery/result.py\\\", line 326, in throw\\n    self.on_ready.throw(*args, **kwargs)\\n  File \\\"/Users/hamedbabaeian/MergedSkyNet/Backend/env/lib/python3.7/site-packages/vine/promises.py\\\", line 244, in throw\\n    reraise(type(exc), exc, tb)\\n  File \\\"/Users/hamedbabaeian/MergedSkyNet/Backend/env/lib/python3.7/site-packages/vine/five.py\\\", line 195, in reraise\\n    raise value\\nFileNotFoundError: [Errno 2] No such file or directory\\n\"}, {\"time\": 1612259695, \"error_code\": 503, \"message\": \"Service down\", \"payload\": {\"payload\": \"[Errno 2] No such file or directory\"}, \"stack_trace\": \"Traceback (most recent call last):\\n  File \\\"/Users/hamedbabaeian/MergedSkyNet/Backend/core.py\\\", line 2023, in get_withdrawable_amount\\n    amount = _internal_task_manager.get_withdrawable_amount(user_id)\\n  File \\\"/Users/hamedbabaeian/MergedSkyNet/Backend/internal_task_manager.py\\\", line 274, in get_withdrawable_amount\\n    return {**amount_task_dump.get(), **amount_task.get()}\\n  File \\\"/Users/hamedbabaeian/MergedSkyNet/Backend/env/lib/python3.7/site-packages/celery/result.py\\\", line 211, in get\\n    self._maybe_reraise_parent_error()\\n  File \\\"/Users/hamedbabaeian/MergedSkyNet/Backend/env/lib/python3.7/site-packages/celery/result.py\\\", line 234, in _maybe_reraise_parent_error\\n    node.maybe_throw()\\n  File \\\"/Users/hamedbabaeian/MergedSkyNet/Backend/env/lib/python3.7/site-packages/celery/result.py\\\", line 333, in maybe_throw\\n    self.throw(value, self._to_remote_traceback(tb))\\n  File \\\"/Users/hamedbabaeian/MergedSkyNet/Backend/env/lib/python3.7/site-packages/celery/result.py\\\", line 326, in throw\\n    self.on_ready.throw(*args, **kwargs)\\n  File \\\"/Users/hamedbabaeian/MergedSkyNet/Backend/env/lib/python3.7/site-packages/vine/promises.py\\\", line 244, in throw\\n    reraise(type(exc), exc, tb)\\n  File \\\"/Users/hamedbabaeian/MergedSkyNet/Backend/env/lib/python3.7/site-packages/vine/five.py\\\", line 195, in reraise\\n    raise value\\nFileNotFoundError: [Errno 2] No such file or directory\\n\"}, {\"time\": 1612259683, \"error_code\": 503, \"message\": \"Service down\", \"payload\": {\"payload\": \"[Errno 2] No such file or directory\"}, \"stack_trace\": \"Traceback (most recent call last):\\n  File \\\"/Users/hamedbabaeian/MergedSkyNet/Backend/core.py\\\", line 2023, in get_withdrawable_amount\\n    amount = _internal_task_manager.get_withdrawable_amount(user_id)\\n  File \\\"/Users/hamedbabaeian/MergedSkyNet/Backend/internal_task_manager.py\\\", line 274, in get_withdrawable_amount\\n    return {**amount_task_dump.get(), **amount_task.get()}\\n  File \\\"/Users/hamedbabaeian/MergedSkyNet/Backend/env/lib/python3.7/site-packages/celery/result.py\\\", line 211, in get\\n    self._maybe_reraise_parent_error()\\n  File \\\"/Users/hamedbabaeian/MergedSkyNet/Backend/env/lib/python3.7/site-packages/celery/result.py\\\", line 234, in _maybe_reraise_parent_error\\n    node.maybe_throw()\\n  File \\\"/Users/hamedbabaeian/MergedSkyNet/Backend/env/lib/python3.7/site-packages/celery/result.py\\\", line 333, in maybe_throw\\n    self.throw(value, self._to_remote_traceback(tb))\\n  File \\\"/Users/hamedbabaeian/MergedSkyNet/Backend/env/lib/python3.7/site-packages/celery/result.py\\\", line 326, in throw\\n    self.on_ready.throw(*args, **kwargs)\\n  File \\\"/Users/hamedbabaeian/MergedSkyNet/Backend/env/lib/python3.7/site-packages/vine/promises.py\\\", line 244, in throw\\n    reraise(type(exc), exc, tb)\\n  File \\\"/Users/hamedbabaeian/MergedSkyNet/Backend/env/lib/python3.7/site-packages/vine/five.py\\\", line 195, in reraise\\n    raise value\\nFileNotFoundError: [Errno 2] No such file or directory\\n\"}, {\"time\": 1612259682, \"error_code\": 503, \"message\": \"Service down\", \"payload\": {\"payload\": \"[Errno 2] No such file or directory\"}, \"stack_trace\": \"Traceback (most recent call last):\\n  File \\\"/Users/hamedbabaeian/MergedSkyNet/Backend/core.py\\\", line 2023, in get_withdrawable_amount\\n    amount = _internal_task_manager.get_withdrawable_amount(user_id)\\n  File \\\"/Users/hamedbabaeian/MergedSkyNet/Backend/internal_task_manager.py\\\", line 274, in get_withdrawable_amount\\n    return {**amount_task_dump.get(), **amount_task.get()}\\n  File \\\"/Users/hamedbabaeian/MergedSkyNet/Backend/env/lib/python3.7/site-packages/celery/result.py\\\", line 228, in get\\n    on_message=on_message,\\n  File \\\"/Users/hamedbabaeian/MergedSkyNet/Backend/env/lib/python3.7/site-packages/celery/backends/asynchronous.py\\\", line 200, in wait_for_pending\\n    for _ in self._wait_for_pending(result, **kwargs):\\n  File \\\"/Users/hamedbabaeian/MergedSkyNet/Backend/env/lib/python3.7/site-packages/celery/backends/asynchronous.py\\\", line 268, in _wait_for_pending\\n    on_interval=on_interval):\\n  File \\\"/Users/hamedbabaeian/MergedSkyNet/Backend/env/lib/python3.7/site-packages/celery/backends/asynchronous.py\\\", line 59, in drain_events_until\\n    on_interval()\\n  File \\\"/Users/hamedbabaeian/MergedSkyNet/Backend/env/lib/python3.7/site-packages/vine/promises.py\\\", line 170, in __call__\\n    return self.throw()\\n  File \\\"/Users/hamedbabaeian/MergedSkyNet/Backend/env/lib/python3.7/site-packages/vine/promises.py\\\", line 167, in __call__\\n    retval = fun(*final_args, **final_kwargs)\\n  File \\\"/Users/hamedbabaeian/MergedSkyNet/Backend/env/lib/python3.7/site-packages/celery/result.py\\\", line 234, in _maybe_reraise_parent_error\\n    node.maybe_throw()\\n  File \\\"/Users/hamedbabaeian/MergedSkyNet/Backend/env/lib/python3.7/site-packages/celery/result.py\\\", line 333, in maybe_throw\\n    self.throw(value, self._to_remote_traceback(tb))\\n  File \\\"/Users/hamedbabaeian/MergedSkyNet/Backend/env/lib/python3.7/site-packages/celery/result.py\\\", line 326, in throw\\n    self.on_ready.throw(*args, **kwargs)\\n  File \\\"/Users/hamedbabaeian/MergedSkyNet/Backend/env/lib/python3.7/site-packages/vine/promises.py\\\", line 244, in throw\\n    reraise(type(exc), exc, tb)\\n  File \\\"/Users/hamedbabaeian/MergedSkyNet/Backend/env/lib/python3.7/site-packages/vine/five.py\\\", line 195, in reraise\\n    raise value\\nFileNotFoundError: [Errno 2] No such file or directory\\n\"}, {\"time\": 1612259682, \"error_code\": 503, \"message\": \"Service down\", \"payload\": {\"payload\": \"[Errno 2] No such file or directory\"}, \"stack_trace\": \"Traceback (most recent call last):\\n  File \\\"/Users/hamedbabaeian/MergedSkyNet/Backend/core.py\\\", line 1059, in get_user_subscribed_strategies\\n    end=end)\\n  File \\\"/Users/hamedbabaeian/MergedSkyNet/Backend/internal_task_manager.py\\\", line 98, in get_user_subscribed_strategies\\n    args=(user_id, int(size), int(page), sort, order, begin, end), queue='strategies').get()\\n  File \\\"/Users/hamedbabaeian/MergedSkyNet/Backend/env/lib/python3.7/site-packages/celery/result.py\\\", line 228, in get\\n    on_message=on_message,\\n  File \\\"/Users/hamedbabaeian/MergedSkyNet/Backend/env/lib/python3.7/site-packages/celery/backends/asynchronous.py\\\", line 202, in wait_for_pending\\n    return result.maybe_throw(callback=callback, propagate=propagate)\\n  File \\\"/Users/hamedbabaeian/MergedSkyNet/Backend/env/lib/python3.7/site-packages/celery/result.py\\\", line 333, in maybe_throw\\n    self.throw(value, self._to_remote_traceback(tb))\\n  File \\\"/Users/hamedbabaeian/MergedSkyNet/Backend/env/lib/python3.7/site-packages/celery/result.py\\\", line 326, in throw\\n    self.on_ready.throw(*args, **kwargs)\\n  File \\\"/Users/hamedbabaeian/MergedSkyNet/Backend/env/lib/python3.7/site-packages/vine/promises.py\\\", line 244, in throw\\n    reraise(type(exc), exc, tb)\\n  File \\\"/Users/hamedbabaeian/MergedSkyNet/Backend/env/lib/python3.7/site-packages/vine/five.py\\\", line 195, in reraise\\n    raise value\\nFileNotFoundError: [Errno 2] No such file or directory\\n\"}, {\"time\": 1612259681, \"error_code\": 503, \"message\": \"Service down\", \"payload\": {\"payload\": \"[Errno 2] No such file or directory\"}, \"stack_trace\": \"Traceback (most recent call last):\\n  File \\\"/Users/hamedbabaeian/MergedSkyNet/Backend/core.py\\\", line 1059, in get_user_subscribed_strategies\\n    end=end)\\n  File \\\"/Users/hamedbabaeian/MergedSkyNet/Backend/internal_task_manager.py\\\", line 98, in get_user_subscribed_strategies\\n    args=(user_id, int(size), int(page), sort, order, begin, end), queue='strategies').get()\\n  File \\\"/Users/hamedbabaeian/MergedSkyNet/Backend/env/lib/python3.7/site-packages/celery/result.py\\\", line 228, in get\\n    on_message=on_message,\\n  File \\\"/Users/hamedbabaeian/MergedSkyNet/Backend/env/lib/python3.7/site-packages/celery/backends/asynchronous.py\\\", line 202, in wait_for_pending\\n    return result.maybe_throw(callback=callback, propagate=propagate)\\n  File \\\"/Users/hamedbabaeian/MergedSkyNet/Backend/env/lib/python3.7/site-packages/celery/result.py\\\", line 333, in maybe_throw\\n    self.throw(value, self._to_remote_traceback(tb))\\n  File \\\"/Users/hamedbabaeian/MergedSkyNet/Backend/env/lib/python3.7/site-packages/celery/result.py\\\", line 326, in throw\\n    self.on_ready.throw(*args, **kwargs)\\n  File \\\"/Users/hamedbabaeian/MergedSkyNet/Backend/env/lib/python3.7/site-packages/vine/promises.py\\\", line 244, in throw\\n    reraise(type(exc), exc, tb)\\n  File \\\"/Users/hamedbabaeian/MergedSkyNet/Backend/env/lib/python3.7/site-packages/vine/five.py\\\", line 195, in reraise\\n    raise value\\nFileNotFoundError: [Errno 2] No such file or directory\\n\"}, {\"time\": 1612258079, \"error_code\": 503, \"message\": \"Service down\", \"payload\": {\"payload\": \"[Errno 2] No such file or directory\"}, \"stack_trace\": \"Traceback (most recent call last):\\n  File \\\"/Users/hamedbabaeian/MergedSkyNet/Backend/core.py\\\", line 481, in get_user_count\\n    stats = _internal_task_manager.get_user_stats(begin, end)\\n  File \\\"/Users/hamedbabaeian/MergedSkyNet/Backend/internal_task_manager.py\\\", line 131, in get_user_stats\\n    for tr in customer_tasks.get(): content.extend(tr)\\n  File \\\"/Users/hamedbabaeian/MergedSkyNet/Backend/env/lib/python3.7/site-packages/celery/result.py\\\", line 703, in get\\n    on_interval=on_interval,\\n  File \\\"/Users/hamedbabaeian/MergedSkyNet/Backend/env/lib/python3.7/site-packages/celery/result.py\\\", line 830, in join_native\\n    raise value\\nFileNotFoundError: [Errno 2] No such file or directory\\n\"}, {\"time\": 1612257444, \"error_code\": 500, \"message\": \"Internal generic error\", \"payload\": {\"payload\": \"localhost:27017: [Errno 61] Connection refused\"}, \"stack_trace\": \"Traceback (most recent call last):\\n  File \\\"/Users/hamedbabaeian/MergedSkyNet/Backend/core.py\\\", line 1133, in login\\n    request.json.get('token', ''))\\n  File \\\"/Users/hamedbabaeian/MergedSkyNet/Backend/task_manager.py\\\", line 230, in login\\n    args=(username, password, token), queue='authentication').get()\\n  File \\\"/Users/hamedbabaeian/MergedSkyNet/Backend/env/lib/python3.7/site-packages/celery/result.py\\\", line 228, in get\\n    on_message=on_message,\\n  File \\\"/Users/hamedbabaeian/MergedSkyNet/Backend/env/lib/python3.7/site-packages/celery/backends/asynchronous.py\\\", line 202, in wait_for_pending\\n    return result.maybe_throw(callback=callback, propagate=propagate)\\n  File \\\"/Users/hamedbabaeian/MergedSkyNet/Backend/env/lib/python3.7/site-packages/celery/result.py\\\", line 333, in maybe_throw\\n    self.throw(value, self._to_remote_traceback(tb))\\n  File \\\"/Users/hamedbabaeian/MergedSkyNet/Backend/env/lib/python3.7/site-packages/celery/result.py\\\", line 326, in throw\\n    self.on_ready.throw(*args, **kwargs)\\n  File \\\"/Users/hamedbabaeian/MergedSkyNet/Backend/env/lib/python3.7/site-packages/vine/promises.py\\\", line 244, in throw\\n    reraise(type(exc), exc, tb)\\n  File \\\"/Users/hamedbabaeian/MergedSkyNet/Backend/env/lib/python3.7/site-packages/vine/five.py\\\", line 195, in reraise\\n    raise value\\npymongo.errors.ServerSelectionTimeoutError: localhost:27017: [Errno 61] Connection refused\\n\"}]")

    def test_get_audits_mutation_0(self):
        task = diagnostics_service.get_audits.s(
            None, None, 'ADMIN', '10'
        ).apply()
        self.assertEqual(task.result, "[{\"time\": 1612259899, \"username\": \"ADMIN\", \"caller\": \"get_audits\"}, {\"time\": 1612259890, \"username\": \"ADMIN\", \"caller\": \"get_diagnostics\"}, {\"time\": 1612259889, \"username\": \"ADMIN\", \"caller\": \"get_diagnostics\"}, {\"time\": 1612259883, \"username\": \"ADMIN\", \"caller\": \"get_skynet_users\"}, {\"time\": 1612259882, \"username\": \"ADMIN\", \"caller\": \"get_skynet_users\"}, {\"time\": 1612259841, \"username\": \"ADMIN\", \"caller\": \"get_active_strategy_names\"}, {\"time\": 1612259840, \"username\": \"ADMIN\", \"caller\": \"get_active_strategy_names\"}, {\"time\": 1612259817, \"username\": \"ADMIN\", \"caller\": \"get_active_strategy_names\"}, {\"time\": 1612259816, \"username\": \"ADMIN\", \"caller\": \"get_active_strategy_names\"}, {\"time\": 1612259790, \"username\": \"ADMIN\", \"caller\": \"get_active_strategy_names\"}]")

    def test_get_audits_mutation_0(self):
        task = diagnostics_service.get_audits.s(
            None, None, 'ADMIN', '10'
        ).apply()
        self.assertEqual(task.result, "[{\"time\": 1612259900, \"username\": \"ADMIN\", \"caller\": \"get_audits\"}, {\"time\": 1612259899, \"username\": \"ADMIN\", \"caller\": \"get_audits\"}, {\"time\": 1612259890, \"username\": \"ADMIN\", \"caller\": \"get_diagnostics\"}, {\"time\": 1612259889, \"username\": \"ADMIN\", \"caller\": \"get_diagnostics\"}, {\"time\": 1612259883, \"username\": \"ADMIN\", \"caller\": \"get_skynet_users\"}, {\"time\": 1612259882, \"username\": \"ADMIN\", \"caller\": \"get_skynet_users\"}, {\"time\": 1612259841, \"username\": \"ADMIN\", \"caller\": \"get_active_strategy_names\"}, {\"time\": 1612259840, \"username\": \"ADMIN\", \"caller\": \"get_active_strategy_names\"}, {\"time\": 1612259817, \"username\": \"ADMIN\", \"caller\": \"get_active_strategy_names\"}, {\"time\": 1612259816, \"username\": \"ADMIN\", \"caller\": \"get_active_strategy_names\"}]")

if __name__ == '__main__':
    unittest.main(verbosity=2)
